Workbook
Name _: #REF!
Name __: #REF!
Name ___: #REF!
Name _____: #REF!
Name _______: #REF!
Name ________________a1: #N/A
Name ________________a10: #N/A
Name ________________a11: #N/A
Name ________________a12: #N/A
Name ________________a13: #N/A
Name ________________a14: #N/A
Name ________________a15: #N/A
Name ________________a16: #N/A
Name ________________a17: #N/A
Name ________________a2: #N/A
Name ________________a3: #N/A
Name ________________a4: #N/A
Name ________________a5: #N/A
Name ________________a6: #N/A
Name ________________a7: #N/A
Name ________________a8: #N/A
Name ________________a9: #N/A
Name _______________a1: #N/A
Name _______________a10: #N/A
Name _______________a11: #N/A
Name _______________a12: #N/A
Name _______________a13: #N/A
Name _______________a14: #N/A
Name _______________a15: #N/A
Name _______________a16: #N/A
Name _______________a17: #N/A
Name _______________a2: #N/A
Name _______________a3: #N/A
Name _______________a4: #N/A
Name _______________a5: #N/A
Name _______________a6: #N/A
Name _______________a7: #N/A
Name _______________a8: #N/A
Name _______________a9: #N/A
Name _______________sp1: #REF!
Name _______________sp2: #REF!
Name _______________sp3: #REF!
Name ______________a1: #N/A
Name ______________a10: #N/A
Name ______________a11: #N/A
Name ______________a12: #N/A
Name ______________a13: #N/A
Name ______________a14: #N/A
Name ______________a15: #N/A
Name ______________a16: #N/A
Name ______________a17: #N/A
Name ______________A18: #REF!
Name ______________A19: #REF!
Name ______________a2: #N/A
Name ______________a20: #REF!
Name ______________A21: #REF!
Name ______________A22: #REF!
Name ______________A23: #REF!
Name ______________A24: #REF!
Name ______________A25: #REF!

Sheet sheet
A1: 회사명 | I1: 2026 | M1: 년 | O1: 2 | Q1: 월 | S1: 노무비지급대장 | AD1: 기 간 | AE1: =DATE($I$1,$O$1,1) -> 46054 | AG1: 고용보험 | AH1: 0.9 | AI1: 적용일수 | AJ1: 8 | AK1: 이 노임대장은 단순 월력으로 건강 및 연금 | BG1: 매사 작업 내역서
A2: 현장명 | AE2: =DATE($I$1,$O$1+1,0) -> 46081 | AG2: 건강보험 | AH2: 3.545 | AI2: ※ 변경 사항이 있을 경우, 수정하여 주시면 변경 적용됩니다! | AK2: 공제금액이 산정됩니다. | BY2: ▶ 월 수정
A3: 현장책임자 | H3: 관리번호 | Y3: ※ 프로그램 등록 후에 총 인원수, 총 공수, 총 일수, 노무비 총액 일치 꼭 확인해 주시기 바랍니다. | AG3: 장기요양 | AH3: 0.9182 | AK3: 건강 및 연금 가입 지침에 따라, 명확한 공제 | BV3: =I1 -> 2026 | BW3: =O1 -> 2 | BY3: ▶ 현장명 수정
A4: 총 인원수 : | C4: =COUNTA(C8:C1001) -> 0 | D4: ※ 프로그램 등록 용 노임대장입니다. 실제 보험료 부과내역은 프로그램에서 확인하시기 바랍니다. ※ 셀 삽입 시, 수식이 적용되지 않을 수 있으므로 수식 적용 여부 꼭 확인해 주시기 바랍니다. | H4: 합 계 | I4: =SUMPRODUCT((MOD(ROW(I$8:I$1001),2)=0)*I$8:I$1001) -> 0 | J4: =SUMPRODUCT((MOD(ROW(J$8:J$1001),2)=0)*J$8:J$1001) -> 4 | K4: =SUMPRODUCT((MOD(ROW(K$8:K$1001),2)=0)*K$8:K$1001) -> 4 | L4: =SUMPRODUCT((MOD(ROW(L$8:L$1001),2)=0)*L$8:L$1001) -> 1 | M4: =SUMPRODUCT((MOD(ROW(M$8:M$1001),2)=0)*M$8:M$1001) -> 1 | N4: =SUMPRODUCT((MOD(ROW(N$8:N$1001),2)=0)*N$8:N$1001) -> 0 | O4: =SUMPRODUCT((MOD(ROW(O$8:O$1001),2)=0)*O$8:O$1001) -> 2 | P4: =SUMPRODUCT((MOD(ROW(P$8:P$1001),2)=0)*P$8:P$1001) -> 0 | ... W4: =SUMPRODUCT((MOD(ROW(W$8:W$1001),2)=0)*W$8:W$1001) -> 0 | Y4: =SUM(Y8:Y1001) -> 52 | Z4: =SUM(Z8:Z1001) -> 50 | AA4: =SUM(AA8:AA1001) -> 0 | AB4: =SUMPRODUCT((MOD(ROW(AB$8:AB$1001),2)=0)*AB$8:AB$1001) -> 0 | AC4: =SUMPRODUCT((MOD(ROW(AC$8:AC$1001),2)=0)*AC$8:AC$1001) -> 0 | AD4: =SUMPRODUCT((MOD(ROW(AD$8:AD$1001),2)=0)*AD$8:AD$1001) -> 0 | AE4: =SUM(AE8:AE1001) -> 0 | AF4: =SUM(AF8:AF1001) -> 0 | AG4: 연금보험 | AH4: 4.5 | AI4: 연금고시금액 | AJ4: 2200000 | AK4: 금액을 확인하시려면 꼭 프로그램에 등록 후 | BG4: 현장명 : | BU4: 합 계 | BV4: =SUM(BV8:BV33) -> 0 | BY4: ▶ 현장 책임자 수정
I5: =SUMPRODUCT((MOD(ROW(I$8:I$1001),2)=1)*I$8:I$1001) -> 0 | J5: =SUMPRODUCT((MOD(ROW(J$8:J$1001),2)=1)*J$8:J$1001) -> 0 | K5: =SUMPRODUCT((MOD(ROW(K$8:K$1001),2)=1)*K$8:K$1001) -> 0 | L5: =SUMPRODUCT((MOD(ROW(L$8:L$1001),2)=1)*L$8:L$1001) -> 0 | M5: =SUMPRODUCT((MOD(ROW(M$8:M$1001),2)=1)*M$8:M$1001) -> 2 | N5: =SUMPRODUCT((MOD(ROW(N$8:N$1001),2)=1)*N$8:N$1001) -> 4 | O5: =SUMPRODUCT((MOD(ROW(O$8:O$1001),2)=1)*O$8:O$1001) -> 0 | P5: =SUMPRODUCT((MOD(ROW(P$8:P$1001),2)=1)*P$8:P$1001) -> 3 | ... X5: =SUMPRODUCT((MOD(ROW(X$8:X$1001),2)=1)*X$8:X$1001) -> 0 | AB5: =SUMPRODUCT((MOD(ROW(AB$8:AB$1001),2)=1)*AB$8:AB$1001) -> 0 | AC5: =SUMPRODUCT((MOD(ROW(AC$8:AC$1001),2)=1)*AC$8:AC$1001) -> 0 | AD5: =SUMPRODUCT((MOD(ROW(AD$8:AD$1001),2)=1)*AD$8:AD$1001) -> 0 | AG5: 연금상한 | AH5: 6170000 | AI5: 연금상한공제액 | AJ5: =AH5*AH4% -> 277650 | AK5: 공제금액을 확인하셔야 합니다! | BV5: =SUM(BV8:BV33) -> 0 | BY5: ▶ 위임장 및 신분증 작성
A6: 연번 | B6: 오류 확인 | C6: 성 명 | D6: 주민등록번호 | E6: 직종 | F6: 팀명칭 | G6: 주 소 | H6: 일 당 | I6: =AE1 -> 46054 | J6: =I6+1 -> 46055 | K6: =J6+1 -> 46056 | L6: =K6+1 -> 46057 | M6: =L6+1 -> 46058 | N6: =M6+1 -> 46059 | O6: =N6+1 -> 46060 | P6: =O6+1 -> 46061 | Q6: =P6+1 -> 46062 | ... W6: =V6+1 -> 46068 | Y6: 총 공수 | Z6: 총 일수 | AA6: 보수총액 | AB6: 소득세 | AC6: 고용보험 | AD6: 건강보험 | AE6: 공제합계 | AF6: 차감지급액 | AG6: 휴대전화 | AH6: 은행명 | AI6: 계좌번호 | AJ6: 예금주 | AK6: E-mail | AL6: 영문성명 | AM6: 체류자격 | AN6: 만나이 | AO6: 갑근세합계 | AP6: 1 | AQ6: 2 | AR6: 3 | AS6: 4 | AT6: 5 | AU6: 6 | AV6: 7 | AW6: 8 | AX6: 9 | AY6: 10 | AZ6: 11 | BA6: 12 | BB6: 13 | BC6: 14 | BD6: 15 | BG6: 이 름 | BH6: 공 종 | BI6: 구분 | BJ6: 작업부위 | BK6: 외 주 | BN6: 외 주2 | BQ6: 공제내역 | BV6: 금 액 | BW6: 비 고 | BY6: ▶ 매사 공사시 공제 내역과 작업 수량 확인후 총액으로 입금후 단가 산정
I7: =W6+1 -> 46069 | J7: =I7+1 -> 46070 | K7: =J7+1 -> 46071 | L7: =K7+1 -> 46072 | M7: =L7+1 -> 46073 | N7: =M7+1 -> 46074 | O7: =N7+1 -> 46075 | P7: =O7+1 -> 46076 | Q7: =P7+1 -> 46077 | ... U7: =T7+1 -> 46081 | V7: =IFERROR(IF(DAY(DATE($I$1,$O$1+1,0))<COLUMNS($I$7:V$7)+15,"",U7+1),"") | W7: =IFERROR(IF(DAY(DATE($I$1,$O$1+1,0))<COLUMNS($I$7:W$7)+15,"",V7+1),"") | X7: =IFERROR(IF(DAY(DATE($I$1,$O$1+1,0))<COLUMNS($I$7:X$7)+15,"",W7+1),"") | AB7: 지방소득 | AC7: 국민연금 | AD7: 장기요양 | AP7: 16 | AQ7: 17 | AR7: 18 | AS7: 19 | AT7: 20 | AU7: 21 | AV7: 22 | AW7: 23 | AX7: 24 | AY7: 25 | AZ7: 26 | BA7: 27 | BB7: 28 | BC7: 29 | BD7: 30 | BE7: 31 | BI7: 구 분 | BK7: 수량 | BL7: 단가 | BM7: 금액 | BN7: 수량 | BO7: 단가 | BP7: 금액 | BQ7: 공수 | BR7: 아침 | BS7: 점심 | BT7: 기타 | BU7: 계 | BV7: 금액 | BW7: 일당환산
A8: 1 | J8: 1 | K8: 1 | O8: 1 | R8: 1 | S8: 1 | T8: 1 | U8: 1 | Y8: =SUM(I8:X9) -> 16 | Z8: =COUNTIF(I8:X9,">0") -> 15 | AA8: =H8*Y8 -> 0 | AB8: =IF(AO8<1000, 0, AO8) -> 0 | AC8: =IF(IFERROR($AN8<65,FALSE), IF(B8<>"외국인", ROUNDDOWN(AA8*$AH$1%,-1), IF(AND(AM8<>"", ISNUMBER(SEARCH(LEFT(SUBSTITUTE(AM8, "-",""),2), "F2_F5_F6"))), ROUNDDOWN(AA8*$AH$1%,-1), 0)),0) -> 0 | AD8: =IF(Z8>=$AJ$1,ROUNDDOWN(AA8*$AH$2%,-1),0) -> 0 | AE8: =AB8+AC8+AB9+AC9+AD8+AD9 -> 0 | AF8: =AA8-AE8 -> 0 | AN8: =IFERROR(DATEDIF(DATE(IF(ISNUMBER(FIND(MID( SUBSTITUTE(D8, "-",""), 7, 1), "3478")), 2000, 1900)+MID(D8,1,2), MID(D8,3,2), MID(D8,5,2)), TODAY(), "Y"),"") | AO8: =ROUNDDOWN(SUM(AP8:BE9),-1) -> 0 | AP8: =IF($H8*I8>150000,ROUNDDOWN(($H8*I8-150000)*6%*45%,0),0) -> 0 | AQ8: =IF($H8*J8>150000,ROUNDDOWN(($H8*J8-150000)*6%*45%,0),0) -> 0 | AR8: =IF($H8*K8>150000,ROUNDDOWN(($H8*K8-150000)*6%*45%,0),0) -> 0 | AS8: =IF($H8*L8>150000,ROUNDDOWN(($H8*L8-150000)*6%*45%,0),0) -> 0 | AT8: =IF($H8*M8>150000,ROUNDDOWN(($H8*M8-150000)*6%*45%,0),0) -> 0 | AU8: =IF($H8*N8>150000,ROUNDDOWN(($H8*N8-150000)*6%*45%,0),0) -> 0 | AV8: =IF($H8*O8>150000,ROUNDDOWN(($H8*O8-150000)*6%*45%,0),0) -> 0 | AW8: =IF($H8*P8>150000,ROUNDDOWN(($H8*P8-150000)*6%*45%,0),0) -> 0 | ... BD8: =IF($H8*W8>150000,ROUNDDOWN(($H8*W8-150000)*6%*45%,0),0) -> 0 | BG8: =C8 -> 0 | BM8: =BK8*BL8 -> 0 | BP8: =BN8*BO8 -> 0 | BU8: =SUM(BR8:BT9) -> 0 | BV8: =BM8+BP8-BU8 -> 0
M9: 1 | N9: 2 | P9: 1 | Q9: 1 | R9: 1 | S9: 1 | T9: 1 | U9: 1 | AB9: =ROUNDDOWN(AB8*10%,-1) -> 0 | AC9: =IFERROR(IF(AND( OR(COUNTIF(I8:X9, ">0")>=$AJ$1, AA8>=$AJ$4),AN8<60,AA8<=$AH$5),ROUNDDOWN(ROUNDDOWN(AA8,-3)*$AH$4%,-1),IF(AND(COUNTIF(I8:X9,">0")>=$AJ$1,AN8<60,AA8>$AH$5),$AJ$5,0)),0) -> 0 | AD9: =IF(Z8>=$AJ$1,ROUNDDOWN(AD8*$AH$3%/($AH$2*2%),-1),0) -> 0 | AP9: =IF($H8*I9>150000,ROUNDDOWN(($H8*I9-150000)*6%*45%,0),0) -> 0 | AQ9: =IF($H8*J9>150000,ROUNDDOWN(($H8*J9-150000)*6%*45%,0),0) -> 0 | AR9: =IF($H8*K9>150000,ROUNDDOWN(($H8*K9-150000)*6%*45%,0),0) -> 0 | AS9: =IF($H8*L9>150000,ROUNDDOWN(($H8*L9-150000)*6%*45%,0),0) -> 0 | AT9: =IF($H8*M9>150000,ROUNDDOWN(($H8*M9-150000)*6%*45%,0),0) -> 0 | AU9: =IF($H8*N9>150000,ROUNDDOWN(($H8*N9-150000)*6%*45%,0),0) -> 0 | AV9: =IF($H8*O9>150000,ROUNDDOWN(($H8*O9-150000)*6%*45%,0),0) -> 0 | AW9: =IF($H8*P9>150000,ROUNDDOWN(($H8*P9-150000)*6%*45%,0),0) -> 0 | ... BE9: =IF($H8*X9>150000,ROUNDDOWN(($H8*X9-150000)*6%*45%,0),0) -> 0
A10: 2 | J10: 1 | K10: 1 | L10: 1 | M10: 1 | O10: 1 | Q10: 1 | S10: 1 | T10: 1 | U10: 1 | Y10: =SUM(I10:X11) -> 18 | Z10: =COUNTIF(I10:X11,">0") -> 17 | AA10: =H10*Y10 -> 0 | AB10: =IF(AO10<1000, 0, AO10) -> 0 | AC10: =IF(IFERROR($AN10<65,FALSE), IF(B10<>"외국인", ROUNDDOWN(AA10*$AH$1%,-1), IF(AND(AM10<>"", ISNUMBER(SEARCH(LEFT(SUBSTITUTE(AM10, "-",""),2), "F2_F5_F6"))), ROUNDDOWN(AA10*$AH$1%,-1), 0)),0) -> 0 | AD10: =IF(Z10>=$AJ$1,ROUNDDOWN(AA10*$AH$2%,-1),0) -> 0 | AE10: =AB10+AC10+AB11+AC11+AD10+AD11 -> 0 | AF10: =AA10-AE10 -> 0 | AN10: =IFERROR(DATEDIF(DATE(IF(ISNUMBER(FIND(MID( SUBSTITUTE(D10, "-",""), 7, 1), "3478")), 2000, 1900)+MID(D10,1,2), MID(D10,3,2), MID(D10,5,2)), TODAY(), "Y"),"") | AO10: =ROUNDDOWN(SUM(AP10:BE11),-1) -> 0 | AP10: =IF($H10*I10>150000,ROUNDDOWN(($H10*I10-150000)*6%*45%,0),0) -> 0 | AQ10: =IF($H10*J10>150000,ROUNDDOWN(($H10*J10-150000)*6%*45%,0),0) -> 0 | AR10: =IF($H10*K10>150000,ROUNDDOWN(($H10*K10-150000)*6%*45%,0),0) -> 0 | AS10: =IF($H10*L10>150000,ROUNDDOWN(($H10*L10-150000)*6%*45%,0),0) -> 0 | AT10: =IF($H10*M10>150000,ROUNDDOWN(($H10*M10-150000)*6%*45%,0),0) -> 0 | AU10: =IF($H10*N10>150000,ROUNDDOWN(($H10*N10-150000)*6%*45%,0),0) -> 0 | AV10: =IF($H10*O10>150000,ROUNDDOWN(($H10*O10-150000)*6%*45%,0),0) -> 0 | AW10: =IF($H10*P10>150000,ROUNDDOWN(($H10*P10-150000)*6%*45%,0),0) -> 0 | ... BD10: =IF($H10*W10>150000,ROUNDDOWN(($H10*W10-150000)*6%*45%,0),0) -> 0 | BG10: =C10 -> 0 | BM10: =BK10*BL10 -> 0 | BP10: =BN10*BO10 -> 0 | BU10: =SUM(BR10:BT11) -> 0 | BV10: =BM10+BP10-BU10 -> 0
M11: 1 | N11: 2 | P11: 1 | Q11: 1 | R11: 1 | S11: 1 | T11: 1 | U11: 1 | AB11: =ROUNDDOWN(AB10*10%,-1) -> 0 | AC11: =IFERROR(IF(AND( OR(COUNTIF(I10:X11, ">0")>=$AJ$1, AA10>=$AJ$4),AN10<60,AA10<=$AH$5),ROUNDDOWN(ROUNDDOWN(AA10,-3)*$AH$4%,-1),IF(AND(COUNTIF(I10:X11,">0")>=$AJ$1,AN10<60,AA10>$AH$5),$AJ$5,0)),0) -> 0 | AD11: =IF(Z10>=$AJ$1,ROUNDDOWN(AD10*$AH$3%/($AH$2*2%),-1),0) -> 0 | AP11: =IF($H10*I11>150000,ROUNDDOWN(($H10*I11-150000)*6%*45%,0),0) -> 0 | AQ11: =IF($H10*J11>150000,ROUNDDOWN(($H10*J11-150000)*6%*45%,0),0) -> 0 | AR11: =IF($H10*K11>150000,ROUNDDOWN(($H10*K11-150000)*6%*45%,0),0) -> 0 | AS11: =IF($H10*L11>150000,ROUNDDOWN(($H10*L11-150000)*6%*45%,0),0) -> 0 | AT11: =IF($H10*M11>150000,ROUNDDOWN(($H10*M11-150000)*6%*45%,0),0) -> 0 | AU11: =IF($H10*N11>150000,ROUNDDOWN(($H10*N11-150000)*6%*45%,0),0) -> 0 | AV11: =IF($H10*O11>150000,ROUNDDOWN(($H10*O11-150000)*6%*45%,0),0) -> 0 | AW11: =IF($H10*P11>150000,ROUNDDOWN(($H10*P11-150000)*6%*45%,0),0) -> 0 | ... BE11: =IF($H10*X11>150000,ROUNDDOWN(($H10*X11-150000)*6%*45%,0),0) -> 0
A12: 3 | J12: 1 | K12: 1 | Y12: =SUM(I12:X13) -> 2 | Z12: =COUNTIF(I12:X13,">0") -> 2 | AA12: =H12*Y12 -> 0 | AB12: =IF(AO12<1000, 0, AO12) -> 0 | AC12: =IF(IFERROR($AN12<65,FALSE), IF(B12<>"외국인", ROUNDDOWN(AA12*$AH$1%,-1), IF(AND(AM12<>"", ISNUMBER(SEARCH(LEFT(SUBSTITUTE(AM12, "-",""),2), "F2_F5_F6"))), ROUNDDOWN(AA12*$AH$1%,-1), 0)),0) -> 0 | AD12: =IF(Z12>=$AJ$1,ROUNDDOWN(AA12*$AH$2%,-1),0) -> 0 | AE12: =AB12+AC12+AB13+AC13+AD12+AD13 -> 0 | AF12: =AA12-AE12 -> 0 | AN12: =IFERROR(DATEDIF(DATE(IF(ISNUMBER(FIND(MID( SUBSTITUTE(D12, "-",""), 7, 1), "3478")), 2000, 1900)+MID(D12,1,2), MID(D12,3,2), MID(D12,5,2)), TODAY(), "Y"),"") | AO12: =ROUNDDOWN(SUM(AP12:BE13),-1) -> 0 | AP12: =IF($H12*I12>150000,ROUNDDOWN(($H12*I12-150000)*6%*45%,0),0) -> 0 | AQ12: =IF($H12*J12>150000,ROUNDDOWN(($H12*J12-150000)*6%*45%,0),0) -> 0 | AR12: =IF($H12*K12>150000,ROUNDDOWN(($H12*K12-150000)*6%*45%,0),0) -> 0 | AS12: =IF($H12*L12>150000,ROUNDDOWN(($H12*L12-150000)*6%*45%,0),0) -> 0 | AT12: =IF($H12*M12>150000,ROUNDDOWN(($H12*M12-150000)*6%*45%,0),0) -> 0 | AU12: =IF($H12*N12>150000,ROUNDDOWN(($H12*N12-150000)*6%*45%,0),0) -> 0 | AV12: =IF($H12*O12>150000,ROUNDDOWN(($H12*O12-150000)*6%*45%,0),0) -> 0 | AW12: =IF($H12*P12>150000,ROUNDDOWN(($H12*P12-150000)*6%*45%,0),0) -> 0 | ... BD12: =IF($H12*W12>150000,ROUNDDOWN(($H12*W12-150000)*6%*45%,0),0) -> 0 | BG12: =C12 -> 0 | BM12: =BK12*BL12 -> 0 | BP12: =BN12*BO12 -> 0 | BU12: =SUM(BR12:BT13) -> 0 | BV12: =BM12+BP12-BU12 -> 0
AB13: =ROUNDDOWN(AB12*10%,-1) -> 0 | AC13: =IFERROR(IF(AND( OR(COUNTIF(I12:X13, ">0")>=$AJ$1, AA12>=$AJ$4),AN12<60,AA12<=$AH$5),ROUNDDOWN(ROUNDDOWN(AA12,-3)*$AH$4%,-1),IF(AND(COUNTIF(I12:X13,">0")>=$AJ$1,AN12<60,AA12>$AH$5),$AJ$5,0)),0) -> 0 | AD13: =IF(Z12>=$AJ$1,ROUNDDOWN(AD12*$AH$3%/($AH$2*2%),-1),0) -> 0 | AP13: =IF($H12*I13>150000,ROUNDDOWN(($H12*I13-150000)*6%*45%,0),0) -> 0 | AQ13: =IF($H12*J13>150000,ROUNDDOWN(($H12*J13-150000)*6%*45%,0),0) -> 0 | AR13: =IF($H12*K13>150000,ROUNDDOWN(($H12*K13-150000)*6%*45%,0),0) -> 0 | AS13: =IF($H12*L13>150000,ROUNDDOWN(($H12*L13-150000)*6%*45%,0),0) -> 0 | AT13: =IF($H12*M13>150000,ROUNDDOWN(($H12*M13-150000)*6%*45%,0),0) -> 0 | AU13: =IF($H12*N13>150000,ROUNDDOWN(($H12*N13-150000)*6%*45%,0),0) -> 0 | AV13: =IF($H12*O13>150000,ROUNDDOWN(($H12*O13-150000)*6%*45%,0),0) -> 0 | AW13: =IF($H12*P13>150000,ROUNDDOWN(($H12*P13-150000)*6%*45%,0),0) -> 0 | ... BE13: =IF($H12*X13>150000,ROUNDDOWN(($H12*X13-150000)*6%*45%,0),0) -> 0
A14: 4 | Y14: =SUM(I14:X15) -> 3 | Z14: =COUNTIF(I14:X15,">0") -> 3 | AA14: =H14*Y14 -> 0 | AB14: =IF(AO14<1000, 0, AO14) -> 0 | AC14: =IF(IFERROR($AN14<65,FALSE), IF(B14<>"외국인", ROUNDDOWN(AA14*$AH$1%,-1), IF(AND(AM14<>"", ISNUMBER(SEARCH(LEFT(SUBSTITUTE(AM14, "-",""),2), "F2_F5_F6"))), ROUNDDOWN(AA14*$AH$1%,-1), 0)),0) -> 0 | AD14: =IF(Z14>=$AJ$1,ROUNDDOWN(AA14*$AH$2%,-1),0) -> 0 | AE14: =AB14+AC14+AB15+AC15+AD14+AD15 -> 0 | AF14: =AA14-AE14 -> 0 | AN14: =IFERROR(DATEDIF(DATE(IF(ISNUMBER(FIND(MID( SUBSTITUTE(D14, "-",""), 7, 1), "3478")), 2000, 1900)+MID(D14,1,2), MID(D14,3,2), MID(D14,5,2)), TODAY(), "Y"),"") | AO14: =ROUNDDOWN(SUM(AP14:BE15),-1) -> 0 | AP14: =IF($H14*I14>150000,ROUNDDOWN(($H14*I14-150000)*6%*45%,0),0) -> 0 | AQ14: =IF($H14*J14>150000,ROUNDDOWN(($H14*J14-150000)*6%*45%,0),0) -> 0 | AR14: =IF($H14*K14>150000,ROUNDDOWN(($H14*K14-150000)*6%*45%,0),0) -> 0 | AS14: =IF($H14*L14>150000,ROUNDDOWN(($H14*L14-150000)*6%*45%,0),0) -> 0 | AT14: =IF($H14*M14>150000,ROUNDDOWN(($H14*M14-150000)*6%*45%,0),0) -> 0 | AU14: =IF($H14*N14>150000,ROUNDDOWN(($H14*N14-150000)*6%*45%,0),0) -> 0 | AV14: =IF($H14*O14>150000,ROUNDDOWN(($H14*O14-150000)*6%*45%,0),0) -> 0 | AW14: =IF($H14*P14>150000,ROUNDDOWN(($H14*P14-150000)*6%*45%,0),0) -> 0 | ... BD14: =IF($H14*W14>150000,ROUNDDOWN(($H14*W14-150000)*6%*45%,0),0) -> 0 | BG14: =C14 -> 0 | BM14: =BK14*BL14 -> 0 | BP14: =BN14*BO14 -> 0 | BU14: =SUM(BR14:BT15) -> 0 | BV14: =BM14+BP14-BU14 -> 0
S15: 1 | T15: 1 | U15: 1 | AB15: =ROUNDDOWN(AB14*10%,-1) -> 0 | AC15: =IFERROR(IF(AND( OR(COUNTIF(I14:X15, ">0")>=$AJ$1, AA14>=$AJ$4),AN14<60,AA14<=$AH$5),ROUNDDOWN(ROUNDDOWN(AA14,-3)*$AH$4%,-1),IF(AND(COUNTIF(I14:X15,">0")>=$AJ$1,AN14<60,AA14>$AH$5),$AJ$5,0)),0) -> 0 | AD15: =IF(Z14>=$AJ$1,ROUNDDOWN(AD14*$AH$3%/($AH$2*2%),-1),0) -> 0 | AP15: =IF($H14*I15>150000,ROUNDDOWN(($H14*I15-150000)*6%*45%,0),0) -> 0 | AQ15: =IF($H14*J15>150000,ROUNDDOWN(($H14*J15-150000)*6%*45%,0),0) -> 0 | AR15: =IF($H14*K15>150000,ROUNDDOWN(($H14*K15-150000)*6%*45%,0),0) -> 0 | AS15: =IF($H14*L15>150000,ROUNDDOWN(($H14*L15-150000)*6%*45%,0),0) -> 0 | AT15: =IF($H14*M15>150000,ROUNDDOWN(($H14*M15-150000)*6%*45%,0),0) -> 0 | AU15: =IF($H14*N15>150000,ROUNDDOWN(($H14*N15-150000)*6%*45%,0),0) -> 0 | AV15: =IF($H14*O15>150000,ROUNDDOWN(($H14*O15-150000)*6%*45%,0),0) -> 0 | AW15: =IF($H14*P15>150000,ROUNDDOWN(($H14*P15-150000)*6%*45%,0),0) -> 0 | ... BE15: =IF($H14*X15>150000,ROUNDDOWN(($H14*X15-150000)*6%*45%,0),0) -> 0
A16: 5 | Y16: =SUM(I16:X17) -> 6 | Z16: =COUNTIF(I16:X17,">0") -> 6 | AA16: =H16*Y16 -> 0 | AB16: =IF(AO16<1000, 0, AO16) -> 0 | AC16: =IF(IFERROR($AN16<65,FALSE), IF(B16<>"외국인", ROUNDDOWN(AA16*$AH$1%,-1), IF(AND(AM16<>"", ISNUMBER(SEARCH(LEFT(SUBSTITUTE(AM16, "-",""),2), "F2_F5_F6"))), ROUNDDOWN(AA16*$AH$1%,-1), 0)),0) -> 0 | AD16: =IF(Z16>=$AJ$1,ROUNDDOWN(AA16*$AH$2%,-1),0) -> 0 | AE16: =AB16+AC16+AB17+AC17+AD16+AD17 -> 0 | AF16: =AA16-AE16 -> 0 | AN16: =IFERROR(DATEDIF(DATE(IF(ISNUMBER(FIND(MID( SUBSTITUTE(D16, "-",""), 7, 1), "3478")), 2000, 1900)+MID(D16,1,2), MID(D16,3,2), MID(D16,5,2)), TODAY(), "Y"),"") | AO16: =ROUNDDOWN(SUM(AP16:BE17),-1) -> 0 | AP16: =IF($H16*I16>150000,ROUNDDOWN(($H16*I16-150000)*6%*45%,0),0) -> 0 | AQ16: =IF($H16*J16>150000,ROUNDDOWN(($H16*J16-150000)*6%*45%,0),0) -> 0 | AR16: =IF($H16*K16>150000,ROUNDDOWN(($H16*K16-150000)*6%*45%,0),0) -> 0 | AS16: =IF($H16*L16>150000,ROUNDDOWN(($H16*L16-150000)*6%*45%,0),0) -> 0 | AT16: =IF($H16*M16>150000,ROUNDDOWN(($H16*M16-150000)*6%*45%,0),0) -> 0 | AU16: =IF($H16*N16>150000,ROUNDDOWN(($H16*N16-150000)*6%*45%,0),0) -> 0 | AV16: =IF($H16*O16>150000,ROUNDDOWN(($H16*O16-150000)*6%*45%,0),0) -> 0 | AW16: =IF($H16*P16>150000,ROUNDDOWN(($H16*P16-150000)*6%*45%,0),0) -> 0 | ... BD16: =IF($H16*W16>150000,ROUNDDOWN(($H16*W16-150000)*6%*45%,0),0) -> 0 | BG16: =C16 -> 0 | BM16: =BK16*BL16 -> 0 | BP16: =BN16*BO16 -> 0 | BU16: =SUM(BR16:BT17) -> 0 | BV16: =BM16+BP16-BU16 -> 0
P17: 1 | Q17: 1 | R17: 1 | S17: 1 | T17: 1 | U17: 1 | AB17: =ROUNDDOWN(AB16*10%,-1) -> 0 | AC17: =IFERROR(IF(AND( OR(COUNTIF(I16:X17, ">0")>=$AJ$1, AA16>=$AJ$4),AN16<60,AA16<=$AH$5),ROUNDDOWN(ROUNDDOWN(AA16,-3)*$AH$4%,-1),IF(AND(COUNTIF(I16:X17,">0")>=$AJ$1,AN16<60,AA16>$AH$5),$AJ$5,0)),0) -> 0 | AD17: =IF(Z16>=$AJ$1,ROUNDDOWN(AD16*$AH$3%/($AH$2*2%),-1),0) -> 0 | AP17: =IF($H16*I17>150000,ROUNDDOWN(($H16*I17-150000)*6%*45%,0),0) -> 0 | AQ17: =IF($H16*J17>150000,ROUNDDOWN(($H16*J17-150000)*6%*45%,0),0) -> 0 | AR17: =IF($H16*K17>150000,ROUNDDOWN(($H16*K17-150000)*6%*45%,0),0) -> 0 | AS17: =IF($H16*L17>150000,ROUNDDOWN(($H16*L17-150000)*6%*45%,0),0) -> 0 | AT17: =IF($H16*M17>150000,ROUNDDOWN(($H16*M17-150000)*6%*45%,0),0) -> 0 | AU17: =IF($H16*N17>150000,ROUNDDOWN(($H16*N17-150000)*6%*45%,0),0) -> 0 | AV17: =IF($H16*O17>150000,ROUNDDOWN(($H16*O17-150000)*6%*45%,0),0) -> 0 | AW17: =IF($H16*P17>150000,ROUNDDOWN(($H16*P17-150000)*6%*45%,0),0) -> 0 | ... BE17: =IF($H16*X17>150000,ROUNDDOWN(($H16*X17-150000)*6%*45%,0),0) -> 0
A18: 8 | R18: 1 | S18: 1 | Y18: =SUM(I18:X19) -> 2 | Z18: =COUNTIF(I18:X19,">0") -> 2 | AA18: =H18*Y18 -> 0 | AB18: =IF(AO18<1000, 0, AO18) -> 0 | AC18: =IF(IFERROR($AN18<65,FALSE), IF(B18<>"외국인", ROUNDDOWN(AA18*$AH$1%,-1), IF(AND(AM18<>"", ISNUMBER(SEARCH(LEFT(SUBSTITUTE(AM18, "-",""),2), "F2_F5_F6"))), ROUNDDOWN(AA18*$AH$1%,-1), 0)),0) -> 0 | AD18: =IF(Z18>=$AJ$1,ROUNDDOWN(AA18*$AH$2%,-1),0) -> 0 | AE18: =AB18+AC18+AB19+AC19+AD18+AD19 -> 0 | AF18: =AA18-AE18 -> 0 | AN18: =IFERROR(DATEDIF(DATE(IF(ISNUMBER(FIND(MID( SUBSTITUTE(D18, "-",""), 7, 1), "3478")), 2000, 1900)+MID(D18,1,2), MID(D18,3,2), MID(D18,5,2)), TODAY(), "Y"),"") | AO18: =ROUNDDOWN(SUM(AP18:BE19),-1) -> 0 | AP18: =IF($H18*I18>150000,ROUNDDOWN(($H18*I18-150000)*6%*45%,0),0) -> 0 | AQ18: =IF($H18*J18>150000,ROUNDDOWN(($H18*J18-150000)*6%*45%,0),0) -> 0 | AR18: =IF($H18*K18>150000,ROUNDDOWN(($H18*K18-150000)*6%*45%,0),0) -> 0 | AS18: =IF($H18*L18>150000,ROUNDDOWN(($H18*L18-150000)*6%*45%,0),0) -> 0 | AT18: =IF($H18*M18>150000,ROUNDDOWN(($H18*M18-150000)*6%*45%,0),0) -> 0 | AU18: =IF($H18*N18>150000,ROUNDDOWN(($H18*N18-150000)*6%*45%,0),0) -> 0 | AV18: =IF($H18*O18>150000,ROUNDDOWN(($H18*O18-150000)*6%*45%,0),0) -> 0 | AW18: =IF($H18*P18>150000,ROUNDDOWN(($H18*P18-150000)*6%*45%,0),0) -> 0 | ... BD18: =IF($H18*W18>150000,ROUNDDOWN(($H18*W18-150000)*6%*45%,0),0) -> 0 | BG18: =C18 -> 0 | BM18: =BK18*BL18 -> 0 | BP18: =BN18*BO18 -> 0 | BU18: =SUM(BR18:BT19) -> 0 | BV18: =BM18+BP18-BU18 -> 0
AB19: =ROUNDDOWN(AB18*10%,-1) -> 0 | AC19: =IFERROR(IF(AND( OR(COUNTIF(I18:X19, ">0")>=$AJ$1, AA18>=$AJ$4),AN18<60,AA18<=$AH$5),ROUNDDOWN(ROUNDDOWN(AA18,-3)*$AH$4%,-1),IF(AND(COUNTIF(I18:X19,">0")>=$AJ$1,AN18<60,AA18>$AH$5),$AJ$5,0)),0) -> 0 | AD19: =IF(Z18>=$AJ$1,ROUNDDOWN(AD18*$AH$3%/($AH$2*2%),-1),0) -> 0 | AP19: =IF($H18*I19>150000,ROUNDDOWN(($H18*I19-150000)*6%*45%,0),0) -> 0 | AQ19: =IF($H18*J19>150000,ROUNDDOWN(($H18*J19-150000)*6%*45%,0),0) -> 0 | AR19: =IF($H18*K19>150000,ROUNDDOWN(($H18*K19-150000)*6%*45%,0),0) -> 0 | AS19: =IF($H18*L19>150000,ROUNDDOWN(($H18*L19-150000)*6%*45%,0),0) -> 0 | AT19: =IF($H18*M19>150000,ROUNDDOWN(($H18*M19-150000)*6%*45%,0),0) -> 0 | AU19: =IF($H18*N19>150000,ROUNDDOWN(($H18*N19-150000)*6%*45%,0),0) -> 0 | AV19: =IF($H18*O19>150000,ROUNDDOWN(($H18*O19-150000)*6%*45%,0),0) -> 0 | AW19: =IF($H18*P19>150000,ROUNDDOWN(($H18*P19-150000)*6%*45%,0),0) -> 0 | ... BE19: =IF($H18*X19>150000,ROUNDDOWN(($H18*X19-150000)*6%*45%,0),0) -> 0
A20: 9 | J20: 1 | K20: 1 | Y20: =SUM(I20:X21) -> 2 | Z20: =COUNTIF(I20:X21,">0") -> 2 | AA20: =H20*Y20 -> 0 | AB20: =IF(AO20<1000, 0, AO20) -> 0 | AC20: =IF(IFERROR($AN20<65,FALSE), IF(B20<>"외국인", ROUNDDOWN(AA20*$AH$1%,-1), IF(AND(AM20<>"", ISNUMBER(SEARCH(LEFT(SUBSTITUTE(AM20, "-",""),2), "F2_F5_F6"))), ROUNDDOWN(AA20*$AH$1%,-1), 0)),0) -> 0 | AD20: =IF(Z20>=$AJ$1,ROUNDDOWN(AA20*$AH$2%,-1),0) -> 0 | AE20: =AB20+AC20+AB21+AC21+AD20+AD21 -> 0 | AF20: =AA20-AE20 -> 0 | AN20: =IFERROR(DATEDIF(DATE(IF(ISNUMBER(FIND(MID( SUBSTITUTE(D20, "-",""), 7, 1), "3478")), 2000, 1900)+MID(D20,1,2), MID(D20,3,2), MID(D20,5,2)), TODAY(), "Y"),"") | AO20: =ROUNDDOWN(SUM(AP20:BE21),-1) -> 0 | AP20: =IF($H20*I20>150000,ROUNDDOWN(($H20*I20-150000)*6%*45%,0),0) -> 0 | AQ20: =IF($H20*J20>150000,ROUNDDOWN(($H20*J20-150000)*6%*45%,0),0) -> 0 | AR20: =IF($H20*K20>150000,ROUNDDOWN(($H20*K20-150000)*6%*45%,0),0) -> 0 | AS20: =IF($H20*L20>150000,ROUNDDOWN(($H20*L20-150000)*6%*45%,0),0) -> 0 | AT20: =IF($H20*M20>150000,ROUNDDOWN(($H20*M20-150000)*6%*45%,0),0) -> 0 | AU20: =IF($H20*N20>150000,ROUNDDOWN(($H20*N20-150000)*6%*45%,0),0) -> 0 | AV20: =IF($H20*O20>150000,ROUNDDOWN(($H20*O20-150000)*6%*45%,0),0) -> 0 | AW20: =IF($H20*P20>150000,ROUNDDOWN(($H20*P20-150000)*6%*45%,0),0) -> 0 | ... BD20: =IF($H20*W20>150000,ROUNDDOWN(($H20*W20-150000)*6%*45%,0),0) -> 0 | BG20: =C20 -> 0 | BM20: =BK20*BL20 -> 0 | BP20: =BN20*BO20 -> 0 | BU20: =SUM(BR20:BT21) -> 0 | BV20: =BM20+BP20-BU20 -> 0
AB21: =ROUNDDOWN(AB20*10%,-1) -> 0 | AC21: =IFERROR(IF(AND( OR(COUNTIF(I20:X21, ">0")>=$AJ$1, AA20>=$AJ$4),AN20<60,AA20<=$AH$5),ROUNDDOWN(ROUNDDOWN(AA20,-3)*$AH$4%,-1),IF(AND(COUNTIF(I20:X21,">0")>=$AJ$1,AN20<60,AA20>$AH$5),$AJ$5,0)),0) -> 0 | AD21: =IF(Z20>=$AJ$1,ROUNDDOWN(AD20*$AH$3%/($AH$2*2%),-1),0) -> 0 | AP21: =IF($H20*I21>150000,ROUNDDOWN(($H20*I21-150000)*6%*45%,0),0) -> 0 | AQ21: =IF($H20*J21>150000,ROUNDDOWN(($H20*J21-150000)*6%*45%,0),0) -> 0 | AR21: =IF($H20*K21>150000,ROUNDDOWN(($H20*K21-150000)*6%*45%,0),0) -> 0 | AS21: =IF($H20*L21>150000,ROUNDDOWN(($H20*L21-150000)*6%*45%,0),0) -> 0 | AT21: =IF($H20*M21>150000,ROUNDDOWN(($H20*M21-150000)*6%*45%,0),0) -> 0 | AU21: =IF($H20*N21>150000,ROUNDDOWN(($H20*N21-150000)*6%*45%,0),0) -> 0 | AV21: =IF($H20*O21>150000,ROUNDDOWN(($H20*O21-150000)*6%*45%,0),0) -> 0 | AW21: =IF($H20*P21>150000,ROUNDDOWN(($H20*P21-150000)*6%*45%,0),0) -> 0 | ... BE21: =IF($H20*X21>150000,ROUNDDOWN(($H20*X21-150000)*6%*45%,0),0) -> 0
A22: 10 | Y22: =SUM(I22:X23) -> 3 | Z22: =COUNTIF(I22:X23,">0") -> 3 | AA22: =H22*Y22 -> 0 | AB22: =IF(AO22<1000, 0, AO22) -> 0 | AC22: =IF(IFERROR($AN22<65,FALSE), IF(B22<>"외국인", ROUNDDOWN(AA22*$AH$1%,-1), IF(AND(AM22<>"", ISNUMBER(SEARCH(LEFT(SUBSTITUTE(AM22, "-",""),2), "F2_F5_F6"))), ROUNDDOWN(AA22*$AH$1%,-1), 0)),0) -> 0 | AD22: =IF(Z22>=$AJ$1,ROUNDDOWN(AA22*$AH$2%,-1),0) -> 0 | AE22: =AB22+AC22+AB23+AC23+AD22+AD23 -> 0 | AF22: =AA22-AE22 -> 0 | AN22: =IFERROR(DATEDIF(DATE(IF(ISNUMBER(FIND(MID( SUBSTITUTE(D22, "-",""), 7, 1), "3478")), 2000, 1900)+MID(D22,1,2), MID(D22,3,2), MID(D22,5,2)), TODAY(), "Y"),"") | AO22: =ROUNDDOWN(SUM(AP22:BE23),-1) -> 0 | AP22: =IF($H22*I22>150000,ROUNDDOWN(($H22*I22-150000)*6%*45%,0),0) -> 0 | AQ22: =IF($H22*J22>150000,ROUNDDOWN(($H22*J22-150000)*6%*45%,0),0) -> 0 | AR22: =IF($H22*K22>150000,ROUNDDOWN(($H22*K22-150000)*6%*45%,0),0) -> 0 | AS22: =IF($H22*L22>150000,ROUNDDOWN(($H22*L22-150000)*6%*45%,0),0) -> 0 | AT22: =IF($H22*M22>150000,ROUNDDOWN(($H22*M22-150000)*6%*45%,0),0) -> 0 | AU22: =IF($H22*N22>150000,ROUNDDOWN(($H22*N22-150000)*6%*45%,0),0) -> 0 | AV22: =IF($H22*O22>150000,ROUNDDOWN(($H22*O22-150000)*6%*45%,0),0) -> 0 | AW22: =IF($H22*P22>150000,ROUNDDOWN(($H22*P22-150000)*6%*45%,0),0) -> 0 | ... BD22: =IF($H22*W22>150000,ROUNDDOWN(($H22*W22-150000)*6%*45%,0),0) -> 0 | BG22: =C22 -> 0 | BM22: =BK22*BL22 -> 0 | BP22: =BN22*BO22 -> 0 | BU22: =SUM(BR22:BT23) -> 0 | BV22: =BM22+BP22-BU22 -> 0
Q23: 1 | R23: 1 | S23: 1 | AB23: =ROUNDDOWN(AB22*10%,-1) -> 0 | AC23: =IFERROR(IF(AND( OR(COUNTIF(I22:X23, ">0")>=$AJ$1, AA22>=$AJ$4),AN22<60,AA22<=$AH$5),ROUNDDOWN(ROUNDDOWN(AA22,-3)*$AH$4%,-1),IF(AND(COUNTIF(I22:X23,">0")>=$AJ$1,AN22<60,AA22>$AH$5),$AJ$5,0)),0) -> 0 | AD23: =IF(Z22>=$AJ$1,ROUNDDOWN(AD22*$AH$3%/($AH$2*2%),-1),0) -> 0 | AP23: =IF($H22*I23>150000,ROUNDDOWN(($H22*I23-150000)*6%*45%,0),0) -> 0 | AQ23: =IF($H22*J23>150000,ROUNDDOWN(($H22*J23-150000)*6%*45%,0),0) -> 0 | AR23: =IF($H22*K23>150000,ROUNDDOWN(($H22*K23-150000)*6%*45%,0),0) -> 0 | AS23: =IF($H22*L23>150000,ROUNDDOWN(($H22*L23-150000)*6%*45%,0),0) -> 0 | AT23: =IF($H22*M23>150000,ROUNDDOWN(($H22*M23-150000)*6%*45%,0),0) -> 0 | AU23: =IF($H22*N23>150000,ROUNDDOWN(($H22*N23-150000)*6%*45%,0),0) -> 0 | AV23: =IF($H22*O23>150000,ROUNDDOWN(($H22*O23-150000)*6%*45%,0),0) -> 0 | AW23: =IF($H22*P23>150000,ROUNDDOWN(($H22*P23-150000)*6%*45%,0),0) -> 0 | ... BE23: =IF($H22*X23>150000,ROUNDDOWN(($H22*X23-150000)*6%*45%,0),0) -> 0
A24: 11 | Y24: =SUM(I24:X25) -> 0 | Z24: =COUNTIF(I24:X25,">0") -> 0 | AA24: =H24*Y24 -> 0 | AB24: =IF(AO24<1000, 0, AO24) -> 0 | AC24: =IF(IFERROR($AN24<65,FALSE), IF(B24<>"외국인", ROUNDDOWN(AA24*$AH$1%,-1), IF(AND(AM24<>"", ISNUMBER(SEARCH(LEFT(SUBSTITUTE(AM24, "-",""),2), "F2_F5_F6"))), ROUNDDOWN(AA24*$AH$1%,-1), 0)),0) -> 0 | AD24: =IF(Z24>=$AJ$1,ROUNDDOWN(AA24*$AH$2%,-1),0) -> 0 | AE24: =AB24+AC24+AB25+AC25+AD24+AD25 -> 0 | AF24: =AA24-AE24 -> 0 | AN24: =IFERROR(DATEDIF(DATE(IF(ISNUMBER(FIND(MID( SUBSTITUTE(D24, "-",""), 7, 1), "3478")), 2000, 1900)+MID(D24,1,2), MID(D24,3,2), MID(D24,5,2)), TODAY(), "Y"),"") | AO24: =ROUNDDOWN(SUM(AP24:BE25),-1) -> 0 | AP24: =IF($H24*I24>150000,ROUNDDOWN(($H24*I24-150000)*6%*45%,0),0) -> 0 | AQ24: =IF($H24*J24>150000,ROUNDDOWN(($H24*J24-150000)*6%*45%,0),0) -> 0 | AR24: =IF($H24*K24>150000,ROUNDDOWN(($H24*K24-150000)*6%*45%,0),0) -> 0 | AS24: =IF($H24*L24>150000,ROUNDDOWN(($H24*L24-150000)*6%*45%,0),0) -> 0 | AT24: =IF($H24*M24>150000,ROUNDDOWN(($H24*M24-150000)*6%*45%,0),0) -> 0 | AU24: =IF($H24*N24>150000,ROUNDDOWN(($H24*N24-150000)*6%*45%,0),0) -> 0 | AV24: =IF($H24*O24>150000,ROUNDDOWN(($H24*O24-150000)*6%*45%,0),0) -> 0 | AW24: =IF($H24*P24>150000,ROUNDDOWN(($H24*P24-150000)*6%*45%,0),0) -> 0 | ... BD24: =IF($H24*W24>150000,ROUNDDOWN(($H24*W24-150000)*6%*45%,0),0) -> 0 | BG24: =C24 -> 0 | BM24: =BK24*BL24 -> 0 | BP24: =BN24*BO24 -> 0 | BU24: =SUM(BR24:BT25) -> 0 | BV24: =BM24+BP24-BU24 -> 0
AB25: =ROUNDDOWN(AB24*10%,-1) -> 0 | AC25: =IFERROR(IF(AND( OR(COUNTIF(I24:X25, ">0")>=$AJ$1, AA24>=$AJ$4),AN24<60,AA24<=$AH$5),ROUNDDOWN(ROUNDDOWN(AA24,-3)*$AH$4%,-1),IF(AND(COUNTIF(I24:X25,">0")>=$AJ$1,AN24<60,AA24>$AH$5),$AJ$5,0)),0) -> 0 | AD25: =IF(Z24>=$AJ$1,ROUNDDOWN(AD24*$AH$3%/($AH$2*2%),-1),0) -> 0 | AP25: =IF($H24*I25>150000,ROUNDDOWN(($H24*I25-150000)*6%*45%,0),0) -> 0 | AQ25: =IF($H24*J25>150000,ROUNDDOWN(($H24*J25-150000)*6%*45%,0),0) -> 0 | AR25: =IF($H24*K25>150000,ROUNDDOWN(($H24*K25-150000)*6%*45%,0),0) -> 0 | AS25: =IF($H24*L25>150000,ROUNDDOWN(($H24*L25-150000)*6%*45%,0),0) -> 0 | AT25: =IF($H24*M25>150000,ROUNDDOWN(($H24*M25-150000)*6%*45%,0),0) -> 0 | AU25: =IF($H24*N25>150000,ROUNDDOWN(($H24*N25-150000)*6%*45%,0),0) -> 0 | AV25: =IF($H24*O25>150000,ROUNDDOWN(($H24*O25-150000)*6%*45%,0),0) -> 0 | AW25: =IF($H24*P25>150000,ROUNDDOWN(($H24*P25-150000)*6%*45%,0),0) -> 0 | ... BE25: =IF($H24*X25>150000,ROUNDDOWN(($H24*X25-150000)*6%*45%,0),0) -> 0
A26: 12 | Y26: =SUM(I26:X27) -> 0 | Z26: =COUNTIF(I26:X27,">0") -> 0 | AA26: =H26*Y26 -> 0 | AB26: =IF(AO26<1000, 0, AO26) -> 0 | AC26: =IF(IFERROR($AN26<65,FALSE), IF(B26<>"외국인", ROUNDDOWN(AA26*$AH$1%,-1), IF(AND(AM26<>"", ISNUMBER(SEARCH(LEFT(SUBSTITUTE(AM26, "-",""),2), "F2_F5_F6"))), ROUNDDOWN(AA26*$AH$1%,-1), 0)),0) -> 0 | AD26: =IF(Z26>=$AJ$1,ROUNDDOWN(AA26*$AH$2%,-1),0) -> 0 | AE26: =AB26+AC26+AB27+AC27+AD26+AD27 -> 0 | AF26: =AA26-AE26 -> 0 | AN26: =IFERROR(DATEDIF(DATE(IF(ISNUMBER(FIND(MID( SUBSTITUTE(D26, "-",""), 7, 1), "3478")), 2000, 1900)+MID(D26,1,2), MID(D26,3,2), MID(D26,5,2)), TODAY(), "Y"),"") | AO26: =ROUNDDOWN(SUM(AP26:BE27),-1) -> 0 | AP26: =IF($H26*I26>150000,ROUNDDOWN(($H26*I26-150000)*6%*45%,0),0) -> 0 | AQ26: =IF($H26*J26>150000,ROUNDDOWN(($H26*J26-150000)*6%*45%,0),0) -> 0 | AR26: =IF($H26*K26>150000,ROUNDDOWN(($H26*K26-150000)*6%*45%,0),0) -> 0 | AS26: =IF($H26*L26>150000,ROUNDDOWN(($H26*L26-150000)*6%*45%,0),0) -> 0 | AT26: =IF($H26*M26>150000,ROUNDDOWN(($H26*M26-150000)*6%*45%,0),0) -> 0 | AU26: =IF($H26*N26>150000,ROUNDDOWN(($H26*N26-150000)*6%*45%,0),0) -> 0 | AV26: =IF($H26*O26>150000,ROUNDDOWN(($H26*O26-150000)*6%*45%,0),0) -> 0 | AW26: =IF($H26*P26>150000,ROUNDDOWN(($H26*P26-150000)*6%*45%,0),0) -> 0 | ... BD26: =IF($H26*W26>150000,ROUNDDOWN(($H26*W26-150000)*6%*45%,0),0) -> 0 | BG26: =C26 -> 0 | BM26: =BK26*BL26 -> 0 | BP26: =BN26*BO26 -> 0 | BU26: =SUM(BR26:BT27) -> 0 | BV26: =BM26+BP26-BU26 -> 0
AB27: =ROUNDDOWN(AB26*10%,-1) -> 0 | AC27: =IFERROR(IF(AND( OR(COUNTIF(I26:X27, ">0")>=$AJ$1, AA26>=$AJ$4),AN26<60,AA26<=$AH$5),ROUNDDOWN(ROUNDDOWN(AA26,-3)*$AH$4%,-1),IF(AND(COUNTIF(I26:X27,">0")>=$AJ$1,AN26<60,AA26>$AH$5),$AJ$5,0)),0) -> 0 | AD27: =IF(Z26>=$AJ$1,ROUNDDOWN(AD26*$AH$3%/($AH$2*2%),-1),0) -> 0 | AP27: =IF($H26*I27>150000,ROUNDDOWN(($H26*I27-150000)*6%*45%,0),0) -> 0 | AQ27: =IF($H26*J27>150000,ROUNDDOWN(($H26*J27-150000)*6%*45%,0),0) -> 0 | AR27: =IF($H26*K27>150000,ROUNDDOWN(($H26*K27-150000)*6%*45%,0),0) -> 0 | AS27: =IF($H26*L27>150000,ROUNDDOWN(($H26*L27-150000)*6%*45%,0),0) -> 0 | AT27: =IF($H26*M27>150000,ROUNDDOWN(($H26*M27-150000)*6%*45%,0),0) -> 0 | AU27: =IF($H26*N27>150000,ROUNDDOWN(($H26*N27-150000)*6%*45%,0),0) -> 0 | AV27: =IF($H26*O27>150000,ROUNDDOWN(($H26*O27-150000)*6%*45%,0),0) -> 0 | AW27: =IF($H26*P27>150000,ROUNDDOWN(($H26*P27-150000)*6%*45%,0),0) -> 0 | ... BE27: =IF($H26*X27>150000,ROUNDDOWN(($H26*X27-150000)*6%*45%,0),0) -> 0
A28: 13 | B28: =IF(LEN(D28)>1,IF(VALUE(MID(RIGHT(D28,7),1,1))>4,"외국인",IF(VALUE(RIGHT(11-MOD((MID(D28,1,1)*2+MID(D28,2,1)*3+MID(D28,3,1)*4+MID(D28,4,1)*5+MID(D28,5,1)*6+MID(D28,6,1)*7+MID(RIGHT(D28,7),1,1)*8+MID(RIGHT(D28,7),2,1)*9+MID(RIGHT(D28,7),3,1)*2+MID(RIGHT(D28,7),4,1)*3+MID(RIGHT(D28,7),5,1)*4+MID(RIGHT(D28,7),6,1)*5),11),1))=VALUE(RIGHT(D28,1)),"","오류")),"") | Y28: =SUM(I28:X29) -> 0 | Z28: =COUNTIF(I28:X29,">0") -> 0 | AA28: =H28*Y28 -> 0 | AB28: =IF(AO28<1000, 0, AO28) -> 0 | AC28: =IF(IFERROR($AN28<65,FALSE), IF(B28<>"외국인", ROUNDDOWN(AA28*$AH$1%,-1), IF(AND(AM28<>"", ISNUMBER(SEARCH(LEFT(SUBSTITUTE(AM28, "-",""),2), "F2_F5_F6"))), ROUNDDOWN(AA28*$AH$1%,-1), 0)),0) -> 0 | AD28: =IF(Z28>=$AJ$1,ROUNDDOWN(AA28*$AH$2%,-1),0) -> 0 | AE28: =AB28+AC28+AB29+AC29+AD28+AD29 -> 0 | AF28: =AA28-AE28 -> 0 | AN28: =IFERROR(DATEDIF(DATE(IF(ISNUMBER(FIND(MID( SUBSTITUTE(D28, "-",""), 7, 1), "3478")), 2000, 1900)+MID(D28,1,2), MID(D28,3,2), MID(D28,5,2)), TODAY(), "Y"),"") | AO28: =ROUNDDOWN(SUM(AP28:BE29),-1) -> 0 | AP28: =IF($H28*I28>150000,ROUNDDOWN(($H28*I28-150000)*6%*45%,0),0) -> 0 | AQ28: =IF($H28*J28>150000,ROUNDDOWN(($H28*J28-150000)*6%*45%,0),0) -> 0 | AR28: =IF($H28*K28>150000,ROUNDDOWN(($H28*K28-150000)*6%*45%,0),0) -> 0 | AS28: =IF($H28*L28>150000,ROUNDDOWN(($H28*L28-150000)*6%*45%,0),0) -> 0 | AT28: =IF($H28*M28>150000,ROUNDDOWN(($H28*M28-150000)*6%*45%,0),0) -> 0 | AU28: =IF($H28*N28>150000,ROUNDDOWN(($H28*N28-150000)*6%*45%,0),0) -> 0 | AV28: =IF($H28*O28>150000,ROUNDDOWN(($H28*O28-150000)*6%*45%,0),0) -> 0 | AW28: =IF($H28*P28>150000,ROUNDDOWN(($H28*P28-150000)*6%*45%,0),0) -> 0 | ... BD28: =IF($H28*W28>150000,ROUNDDOWN(($H28*W28-150000)*6%*45%,0),0) -> 0 | BG28: =C28 -> 0 | BM28: =BK28*BL28 -> 0 | BP28: =BN28*BO28 -> 0 | BU28: =SUM(BR28:BT29) -> 0 | BV28: =BM28+BP28-BU28 -> 0
AB29: =ROUNDDOWN(AB28*10%,-1) -> 0 | AC29: =IFERROR(IF(AND( OR(COUNTIF(I28:X29, ">0")>=$AJ$1, AA28>=$AJ$4),AN28<60,AA28<=$AH$5),ROUNDDOWN(ROUNDDOWN(AA28,-3)*$AH$4%,-1),IF(AND(COUNTIF(I28:X29,">0")>=$AJ$1,AN28<60,AA28>$AH$5),$AJ$5,0)),0) -> 0 | AD29: =IF(Z28>=$AJ$1,ROUNDDOWN(AD28*$AH$3%/($AH$2*2%),-1),0) -> 0 | AP29: =IF($H28*I29>150000,ROUNDDOWN(($H28*I29-150000)*6%*45%,0),0) -> 0 | AQ29: =IF($H28*J29>150000,ROUNDDOWN(($H28*J29-150000)*6%*45%,0),0) -> 0 | AR29: =IF($H28*K29>150000,ROUNDDOWN(($H28*K29-150000)*6%*45%,0),0) -> 0 | AS29: =IF($H28*L29>150000,ROUNDDOWN(($H28*L29-150000)*6%*45%,0),0) -> 0 | AT29: =IF($H28*M29>150000,ROUNDDOWN(($H28*M29-150000)*6%*45%,0),0) -> 0 | AU29: =IF($H28*N29>150000,ROUNDDOWN(($H28*N29-150000)*6%*45%,0),0) -> 0 | AV29: =IF($H28*O29>150000,ROUNDDOWN(($H28*O29-150000)*6%*45%,0),0) -> 0 | AW29: =IF($H28*P29>150000,ROUNDDOWN(($H28*P29-150000)*6%*45%,0),0) -> 0 | ... BE29: =IF($H28*X29>150000,ROUNDDOWN(($H28*X29-150000)*6%*45%,0),0) -> 0
A30: 14 | B30: =IF(LEN(D30)>1,IF(VALUE(MID(RIGHT(D30,7),1,1))>4,"외국인",IF(VALUE(RIGHT(11-MOD((MID(D30,1,1)*2+MID(D30,2,1)*3+MID(D30,3,1)*4+MID(D30,4,1)*5+MID(D30,5,1)*6+MID(D30,6,1)*7+MID(RIGHT(D30,7),1,1)*8+MID(RIGHT(D30,7),2,1)*9+MID(RIGHT(D30,7),3,1)*2+MID(RIGHT(D30,7),4,1)*3+MID(RIGHT(D30,7),5,1)*4+MID(RIGHT(D30,7),6,1)*5),11),1))=VALUE(RIGHT(D30,1)),"","오류")),"") | Y30: =SUM(I30:X31) -> 0 | Z30: =COUNTIF(I30:X31,">0") -> 0 | AA30: =H30*Y30 -> 0 | AB30: =IF(AO30<1000, 0, AO30) -> 0 | AC30: =IF(IFERROR($AN30<65,FALSE), IF(B30<>"외국인", ROUNDDOWN(AA30*$AH$1%,-1), IF(AND(AM30<>"", ISNUMBER(SEARCH(LEFT(SUBSTITUTE(AM30, "-",""),2), "F2_F5_F6"))), ROUNDDOWN(AA30*$AH$1%,-1), 0)),0) -> 0 | AD30: =IF(Z30>=$AJ$1,ROUNDDOWN(AA30*$AH$2%,-1),0) -> 0 | AE30: =AB30+AC30+AB31+AC31+AD30+AD31 -> 0 | AF30: =AA30-AE30 -> 0 | AN30: =IFERROR(DATEDIF(DATE(IF(ISNUMBER(FIND(MID( SUBSTITUTE(D30, "-",""), 7, 1), "3478")), 2000, 1900)+MID(D30,1,2), MID(D30,3,2), MID(D30,5,2)), TODAY(), "Y"),"") | AO30: =ROUNDDOWN(SUM(AP30:BE31),-1) -> 0 | AP30: =IF($H30*I30>150000,ROUNDDOWN(($H30*I30-150000)*6%*45%,0),0) -> 0 | AQ30: =IF($H30*J30>150000,ROUNDDOWN(($H30*J30-150000)*6%*45%,0),0) -> 0 | AR30: =IF($H30*K30>150000,ROUNDDOWN(($H30*K30-150000)*6%*45%,0),0) -> 0 | AS30: =IF($H30*L30>150000,ROUNDDOWN(($H30*L30-150000)*6%*45%,0),0) -> 0 | AT30: =IF($H30*M30>150000,ROUNDDOWN(($H30*M30-150000)*6%*45%,0),0) -> 0 | AU30: =IF($H30*N30>150000,ROUNDDOWN(($H30*N30-150000)*6%*45%,0),0) -> 0 | AV30: =IF($H30*O30>150000,ROUNDDOWN(($H30*O30-150000)*6%*45%,0),0) -> 0 | AW30: =IF($H30*P30>150000,ROUNDDOWN(($H30*P30-150000)*6%*45%,0),0) -> 0 | ... BD30: =IF($H30*W30>150000,ROUNDDOWN(($H30*W30-150000)*6%*45%,0),0) -> 0 | BG30: =C30 -> 0 | BM30: =BK30*BL30 -> 0 | BP30: =BN30*BO30 -> 0 | BU30: =SUM(BR30:BT31) -> 0 | BV30: =BM30+BP30-BU30 -> 0
AB31: =ROUNDDOWN(AB30*10%,-1) -> 0 | AC31: =IFERROR(IF(AND( OR(COUNTIF(I30:X31, ">0")>=$AJ$1, AA30>=$AJ$4),AN30<60,AA30<=$AH$5),ROUNDDOWN(ROUNDDOWN(AA30,-3)*$AH$4%,-1),IF(AND(COUNTIF(I30:X31,">0")>=$AJ$1,AN30<60,AA30>$AH$5),$AJ$5,0)),0) -> 0 | AD31: =IF(Z30>=$AJ$1,ROUNDDOWN(AD30*$AH$3%/($AH$2*2%),-1),0) -> 0 | AP31: =IF($H30*I31>150000,ROUNDDOWN(($H30*I31-150000)*6%*45%,0),0) -> 0 | AQ31: =IF($H30*J31>150000,ROUNDDOWN(($H30*J31-150000)*6%*45%,0),0) -> 0 | AR31: =IF($H30*K31>150000,ROUNDDOWN(($H30*K31-150000)*6%*45%,0),0) -> 0 | AS31: =IF($H30*L31>150000,ROUNDDOWN(($H30*L31-150000)*6%*45%,0),0) -> 0 | AT31: =IF($H30*M31>150000,ROUNDDOWN(($H30*M31-150000)*6%*45%,0),0) -> 0 | AU31: =IF($H30*N31>150000,ROUNDDOWN(($H30*N31-150000)*6%*45%,0),0) -> 0 | AV31: =IF($H30*O31>150000,ROUNDDOWN(($H30*O31-150000)*6%*45%,0),0) -> 0 | AW31: =IF($H30*P31>150000,ROUNDDOWN(($H30*P31-150000)*6%*45%,0),0) -> 0 | ... BE31: =IF($H30*X31>150000,ROUNDDOWN(($H30*X31-150000)*6%*45%,0),0) -> 0
A32: 15 | B32: =IF(LEN(D32)>1,IF(VALUE(MID(RIGHT(D32,7),1,1))>4,"외국인",IF(VALUE(RIGHT(11-MOD((MID(D32,1,1)*2+MID(D32,2,1)*3+MID(D32,3,1)*4+MID(D32,4,1)*5+MID(D32,5,1)*6+MID(D32,6,1)*7+MID(RIGHT(D32,7),1,1)*8+MID(RIGHT(D32,7),2,1)*9+MID(RIGHT(D32,7),3,1)*2+MID(RIGHT(D32,7),4,1)*3+MID(RIGHT(D32,7),5,1)*4+MID(RIGHT(D32,7),6,1)*5),11),1))=VALUE(RIGHT(D32,1)),"","오류")),"") | Y32: =SUM(I32:X33) -> 0 | Z32: =COUNTIF(I32:X33,">0") -> 0 | AA32: =H32*Y32 -> 0 | AB32: =IF(AO32<1000, 0, AO32) -> 0 | AC32: =IF(IFERROR($AN32<65,FALSE), IF(B32<>"외국인", ROUNDDOWN(AA32*$AH$1%,-1), IF(AND(AM32<>"", ISNUMBER(SEARCH(LEFT(SUBSTITUTE(AM32, "-",""),2), "F2_F5_F6"))), ROUNDDOWN(AA32*$AH$1%,-1), 0)),0) -> 0 | AD32: =IF(Z32>=$AJ$1,ROUNDDOWN(AA32*$AH$2%,-1),0) -> 0 | AE32: =AB32+AC32+AB33+AC33+AD32+AD33 -> 0 | AF32: =AA32-AE32 -> 0 | AN32: =IFERROR(DATEDIF(DATE(IF(ISNUMBER(FIND(MID( SUBSTITUTE(D32, "-",""), 7, 1), "3478")), 2000, 1900)+MID(D32,1,2), MID(D32,3,2), MID(D32,5,2)), TODAY(), "Y"),"") | AO32: =ROUNDDOWN(SUM(AP32:BE33),-1) -> 0 | AP32: =IF($H32*I32>150000,ROUNDDOWN(($H32*I32-150000)*6%*45%,0),0) -> 0 | AQ32: =IF($H32*J32>150000,ROUNDDOWN(($H32*J32-150000)*6%*45%,0),0) -> 0 | AR32: =IF($H32*K32>150000,ROUNDDOWN(($H32*K32-150000)*6%*45%,0),0) -> 0 | AS32: =IF($H32*L32>150000,ROUNDDOWN(($H32*L32-150000)*6%*45%,0),0) -> 0 | AT32: =IF($H32*M32>150000,ROUNDDOWN(($H32*M32-150000)*6%*45%,0),0) -> 0 | AU32: =IF($H32*N32>150000,ROUNDDOWN(($H32*N32-150000)*6%*45%,0),0) -> 0 | AV32: =IF($H32*O32>150000,ROUNDDOWN(($H32*O32-150000)*6%*45%,0),0) -> 0 | AW32: =IF($H32*P32>150000,ROUNDDOWN(($H32*P32-150000)*6%*45%,0),0) -> 0 | ... BD32: =IF($H32*W32>150000,ROUNDDOWN(($H32*W32-150000)*6%*45%,0),0) -> 0 | BG32: =C32 -> 0 | BM32: =BK32*BL32 -> 0 | BP32: =BN32*BO32 -> 0 | BU32: =SUM(BR32:BT33) -> 0 | BV32: =BM32+BP32-BU32 -> 0
AB33: =ROUNDDOWN(AB32*10%,-1) -> 0 | AC33: =IFERROR(IF(AND( OR(COUNTIF(I32:X33, ">0")>=$AJ$1, AA32>=$AJ$4),AN32<60,AA32<=$AH$5),ROUNDDOWN(ROUNDDOWN(AA32,-3)*$AH$4%,-1),IF(AND(COUNTIF(I32:X33,">0")>=$AJ$1,AN32<60,AA32>$AH$5),$AJ$5,0)),0) -> 0 | AD33: =IF(Z32>=$AJ$1,ROUNDDOWN(AD32*$AH$3%/($AH$2*2%),-1),0) -> 0 | AP33: =IF($H32*I33>150000,ROUNDDOWN(($H32*I33-150000)*6%*45%,0),0) -> 0 | AQ33: =IF($H32*J33>150000,ROUNDDOWN(($H32*J33-150000)*6%*45%,0),0) -> 0 | AR33: =IF($H32*K33>150000,ROUNDDOWN(($H32*K33-150000)*6%*45%,0),0) -> 0 | AS33: =IF($H32*L33>150000,ROUNDDOWN(($H32*L33-150000)*6%*45%,0),0) -> 0 | AT33: =IF($H32*M33>150000,ROUNDDOWN(($H32*M33-150000)*6%*45%,0),0) -> 0 | AU33: =IF($H32*N33>150000,ROUNDDOWN(($H32*N33-150000)*6%*45%,0),0) -> 0 | AV33: =IF($H32*O33>150000,ROUNDDOWN(($H32*O33-150000)*6%*45%,0),0) -> 0 | AW33: =IF($H32*P33>150000,ROUNDDOWN(($H32*P33-150000)*6%*45%,0),0) -> 0 | ... BE33: =IF($H32*X33>150000,ROUNDDOWN(($H32*X33-150000)*6%*45%,0),0) -> 0
A34: 16 | B34: =IF(LEN(D34)>1,IF(VALUE(MID(RIGHT(D34,7),1,1))>4,"외국인",IF(VALUE(RIGHT(11-MOD((MID(D34,1,1)*2+MID(D34,2,1)*3+MID(D34,3,1)*4+MID(D34,4,1)*5+MID(D34,5,1)*6+MID(D34,6,1)*7+MID(RIGHT(D34,7),1,1)*8+MID(RIGHT(D34,7),2,1)*9+MID(RIGHT(D34,7),3,1)*2+MID(RIGHT(D34,7),4,1)*3+MID(RIGHT(D34,7),5,1)*4+MID(RIGHT(D34,7),6,1)*5),11),1))=VALUE(RIGHT(D34,1)),"","오류")),"") | Y34: =SUM(I34:X35) -> 0 | Z34: =COUNTIF(I34:X35,">0") -> 0 | AA34: =H34*Y34 -> 0 | AB34: =IF(AO34<1000, 0, AO34) -> 0 | AC34: =IF(IFERROR($AN34<65,FALSE), IF(B34<>"외국인", ROUNDDOWN(AA34*$AH$1%,-1), IF(AND(AM34<>"", ISNUMBER(SEARCH(LEFT(SUBSTITUTE(AM34, "-",""),2), "F2_F5_F6"))), ROUNDDOWN(AA34*$AH$1%,-1), 0)),0) -> 0 | AD34: =IF(Z34>=$AJ$1,ROUNDDOWN(AA34*$AH$2%,-1),0) -> 0 | AE34: =AB34+AC34+AB35+AC35+AD34+AD35 -> 0 | AF34: =AA34-AE34 -> 0 | AN34: =IFERROR(DATEDIF(DATE(IF(ISNUMBER(FIND(MID( SUBSTITUTE(D34, "-",""), 7, 1), "3478")), 2000, 1900)+MID(D34,1,2), MID(D34,3,2), MID(D34,5,2)), TODAY(), "Y"),"") | AO34: =ROUNDDOWN(SUM(AP34:BE35),-1) -> 0 | AP34: =IF($H34*I34>150000,ROUNDDOWN(($H34*I34-150000)*6%*45%,0),0) -> 0 | AQ34: =IF($H34*J34>150000,ROUNDDOWN(($H34*J34-150000)*6%*45%,0),0) -> 0 | AR34: =IF($H34*K34>150000,ROUNDDOWN(($H34*K34-150000)*6%*45%,0),0) -> 0 | AS34: =IF($H34*L34>150000,ROUNDDOWN(($H34*L34-150000)*6%*45%,0),0) -> 0 | AT34: =IF($H34*M34>150000,ROUNDDOWN(($H34*M34-150000)*6%*45%,0),0) -> 0 | AU34: =IF($H34*N34>150000,ROUNDDOWN(($H34*N34-150000)*6%*45%,0),0) -> 0 | AV34: =IF($H34*O34>150000,ROUNDDOWN(($H34*O34-150000)*6%*45%,0),0) -> 0 | AW34: =IF($H34*P34>150000,ROUNDDOWN(($H34*P34-150000)*6%*45%,0),0) -> 0 | ... BD34: =IF($H34*W34>150000,ROUNDDOWN(($H34*W34-150000)*6%*45%,0),0) -> 0 | BG34: =C34 -> 0 | BM34: =BK34*BL34 -> 0 | BV34: =BM34+BP34-BU34 -> 0
AB35: =ROUNDDOWN(AB34*10%,-1) -> 0 | AC35: =IFERROR(IF(AND( OR(COUNTIF(I34:X35, ">0")>=$AJ$1, AA34>=$AJ$4),AN34<60,AA34<=$AH$5),ROUNDDOWN(ROUNDDOWN(AA34,-3)*$AH$4%,-1),IF(AND(COUNTIF(I34:X35,">0")>=$AJ$1,AN34<60,AA34>$AH$5),$AJ$5,0)),0) -> 0 | AD35: =IF(Z34>=$AJ$1,ROUNDDOWN(AD34*$AH$3%/($AH$2*2%),-1),0) -> 0 | AP35: =IF($H34*I35>150000,ROUNDDOWN(($H34*I35-150000)*6%*45%,0),0) -> 0 | AQ35: =IF($H34*J35>150000,ROUNDDOWN(($H34*J35-150000)*6%*45%,0),0) -> 0 | AR35: =IF($H34*K35>150000,ROUNDDOWN(($H34*K35-150000)*6%*45%,0),0) -> 0 | AS35: =IF($H34*L35>150000,ROUNDDOWN(($H34*L35-150000)*6%*45%,0),0) -> 0 | AT35: =IF($H34*M35>150000,ROUNDDOWN(($H34*M35-150000)*6%*45%,0),0) -> 0 | AU35: =IF($H34*N35>150000,ROUNDDOWN(($H34*N35-150000)*6%*45%,0),0) -> 0 | AV35: =IF($H34*O35>150000,ROUNDDOWN(($H34*O35-150000)*6%*45%,0),0) -> 0 | AW35: =IF($H34*P35>150000,ROUNDDOWN(($H34*P35-150000)*6%*45%,0),0) -> 0 | ... BE35: =IF($H34*X35>150000,ROUNDDOWN(($H34*X35-150000)*6%*45%,0),0) -> 0
A36: 17 | B36: =IF(LEN(D36)>1,IF(VALUE(MID(RIGHT(D36,7),1,1))>4,"외국인",IF(VALUE(RIGHT(11-MOD((MID(D36,1,1)*2+MID(D36,2,1)*3+MID(D36,3,1)*4+MID(D36,4,1)*5+MID(D36,5,1)*6+MID(D36,6,1)*7+MID(RIGHT(D36,7),1,1)*8+MID(RIGHT(D36,7),2,1)*9+MID(RIGHT(D36,7),3,1)*2+MID(RIGHT(D36,7),4,1)*3+MID(RIGHT(D36,7),5,1)*4+MID(RIGHT(D36,7),6,1)*5),11),1))=VALUE(RIGHT(D36,1)),"","오류")),"") | Y36: =SUM(I36:X37) -> 0 | Z36: =COUNTIF(I36:X37,">0") -> 0 | AA36: =H36*Y36 -> 0 | AB36: =IF(AO36<1000, 0, AO36) -> 0 | AC36: =IF(IFERROR($AN36<65,FALSE), IF(B36<>"외국인", ROUNDDOWN(AA36*$AH$1%,-1), IF(AND(AM36<>"", ISNUMBER(SEARCH(LEFT(SUBSTITUTE(AM36, "-",""),2), "F2_F5_F6"))), ROUNDDOWN(AA36*$AH$1%,-1), 0)),0) -> 0 | AD36: =IF(Z36>=$AJ$1,ROUNDDOWN(AA36*$AH$2%,-1),0) -> 0 | AE36: =AB36+AC36+AB37+AC37+AD36+AD37 -> 0 | AF36: =AA36-AE36 -> 0 | AN36: =IFERROR(DATEDIF(DATE(IF(ISNUMBER(FIND(MID( SUBSTITUTE(D36, "-",""), 7, 1), "3478")), 2000, 1900)+MID(D36,1,2), MID(D36,3,2), MID(D36,5,2)), TODAY(), "Y"),"") | AO36: =ROUNDDOWN(SUM(AP36:BE37),-1) -> 0 | AP36: =IF($H36*I36>150000,ROUNDDOWN(($H36*I36-150000)*6%*45%,0),0) -> 0 | AQ36: =IF($H36*J36>150000,ROUNDDOWN(($H36*J36-150000)*6%*45%,0),0) -> 0 | AR36: =IF($H36*K36>150000,ROUNDDOWN(($H36*K36-150000)*6%*45%,0),0) -> 0 | AS36: =IF($H36*L36>150000,ROUNDDOWN(($H36*L36-150000)*6%*45%,0),0) -> 0 | AT36: =IF($H36*M36>150000,ROUNDDOWN(($H36*M36-150000)*6%*45%,0),0) -> 0 | AU36: =IF($H36*N36>150000,ROUNDDOWN(($H36*N36-150000)*6%*45%,0),0) -> 0 | AV36: =IF($H36*O36>150000,ROUNDDOWN(($H36*O36-150000)*6%*45%,0),0) -> 0 | AW36: =IF($H36*P36>150000,ROUNDDOWN(($H36*P36-150000)*6%*45%,0),0) -> 0 | ... BD36: =IF($H36*W36>150000,ROUNDDOWN(($H36*W36-150000)*6%*45%,0),0) -> 0 | BG36: =C36 -> 0 | BM36: =BK36*BL36 -> 0 | BV36: =BM36+BP36-BU36 -> 0
AB37: =ROUNDDOWN(AB36*10%,-1) -> 0 | AC37: =IFERROR(IF(AND( OR(COUNTIF(I36:X37, ">0")>=$AJ$1, AA36>=$AJ$4),AN36<60,AA36<=$AH$5),ROUNDDOWN(ROUNDDOWN(AA36,-3)*$AH$4%,-1),IF(AND(COUNTIF(I36:X37,">0")>=$AJ$1,AN36<60,AA36>$AH$5),$AJ$5,0)),0) -> 0 | AD37: =IF(Z36>=$AJ$1,ROUNDDOWN(AD36*$AH$3%/($AH$2*2%),-1),0) -> 0 | AP37: =IF($H36*I37>150000,ROUNDDOWN(($H36*I37-150000)*6%*45%,0),0) -> 0 | AQ37: =IF($H36*J37>150000,ROUNDDOWN(($H36*J37-150000)*6%*45%,0),0) -> 0 | AR37: =IF($H36*K37>150000,ROUNDDOWN(($H36*K37-150000)*6%*45%,0),0) -> 0 | AS37: =IF($H36*L37>150000,ROUNDDOWN(($H36*L37-150000)*6%*45%,0),0) -> 0 | AT37: =IF($H36*M37>150000,ROUNDDOWN(($H36*M37-150000)*6%*45%,0),0) -> 0 | AU37: =IF($H36*N37>150000,ROUNDDOWN(($H36*N37-150000)*6%*45%,0),0) -> 0 | AV37: =IF($H36*O37>150000,ROUNDDOWN(($H36*O37-150000)*6%*45%,0),0) -> 0 | AW37: =IF($H36*P37>150000,ROUNDDOWN(($H36*P37-150000)*6%*45%,0),0) -> 0 | ... BE37: =IF($H36*X37>150000,ROUNDDOWN(($H36*X37-150000)*6%*45%,0),0) -> 0
A38: 18 | B38: =IF(LEN(D38)>1,IF(VALUE(MID(RIGHT(D38,7),1,1))>4,"외국인",IF(VALUE(RIGHT(11-MOD((MID(D38,1,1)*2+MID(D38,2,1)*3+MID(D38,3,1)*4+MID(D38,4,1)*5+MID(D38,5,1)*6+MID(D38,6,1)*7+MID(RIGHT(D38,7),1,1)*8+MID(RIGHT(D38,7),2,1)*9+MID(RIGHT(D38,7),3,1)*2+MID(RIGHT(D38,7),4,1)*3+MID(RIGHT(D38,7),5,1)*4+MID(RIGHT(D38,7),6,1)*5),11),1))=VALUE(RIGHT(D38,1)),"","오류")),"") | Y38: =SUM(I38:X39) -> 0 | Z38: =COUNTIF(I38:X39,">0") -> 0 | AA38: =H38*Y38 -> 0 | AB38: =IF(AO38<1000, 0, AO38) -> 0 | AC38: =IF(IFERROR($AN38<65,FALSE), IF(B38<>"외국인", ROUNDDOWN(AA38*$AH$1%,-1), IF(AND(AM38<>"", ISNUMBER(SEARCH(LEFT(SUBSTITUTE(AM38, "-",""),2), "F2_F5_F6"))), ROUNDDOWN(AA38*$AH$1%,-1), 0)),0) -> 0 | AD38: =IF(Z38>=$AJ$1,ROUNDDOWN(AA38*$AH$2%,-1),0) -> 0 | AE38: =AB38+AC38+AB39+AC39+AD38+AD39 -> 0 | AF38: =AA38-AE38 -> 0 | AN38: =IFERROR(DATEDIF(DATE(IF(ISNUMBER(FIND(MID( SUBSTITUTE(D38, "-",""), 7, 1), "3478")), 2000, 1900)+MID(D38,1,2), MID(D38,3,2), MID(D38,5,2)), TODAY(), "Y"),"") | AO38: =ROUNDDOWN(SUM(AP38:BE39),-1) -> 0 | AP38: =IF($H38*I38>150000,ROUNDDOWN(($H38*I38-150000)*6%*45%,0),0) -> 0 | AQ38: =IF($H38*J38>150000,ROUNDDOWN(($H38*J38-150000)*6%*45%,0),0) -> 0 | AR38: =IF($H38*K38>150000,ROUNDDOWN(($H38*K38-150000)*6%*45%,0),0) -> 0 | AS38: =IF($H38*L38>150000,ROUNDDOWN(($H38*L38-150000)*6%*45%,0),0) -> 0 | AT38: =IF($H38*M38>150000,ROUNDDOWN(($H38*M38-150000)*6%*45%,0),0) -> 0 | AU38: =IF($H38*N38>150000,ROUNDDOWN(($H38*N38-150000)*6%*45%,0),0) -> 0 | AV38: =IF($H38*O38>150000,ROUNDDOWN(($H38*O38-150000)*6%*45%,0),0) -> 0 | AW38: =IF($H38*P38>150000,ROUNDDOWN(($H38*P38-150000)*6%*45%,0),0) -> 0 | ... BD38: =IF($H38*W38>150000,ROUNDDOWN(($H38*W38-150000)*6%*45%,0),0) -> 0 | BG38: =C38 -> 0 | BM38: =BK38*BL38 -> 0 | BV38: =BM38+BP38-BU38 -> 0
AB39: =ROUNDDOWN(AB38*10%,-1) -> 0 | AC39: =IFERROR(IF(AND( OR(COUNTIF(I38:X39, ">0")>=$AJ$1, AA38>=$AJ$4),AN38<60,AA38<=$AH$5),ROUNDDOWN(ROUNDDOWN(AA38,-3)*$AH$4%,-1),IF(AND(COUNTIF(I38:X39,">0")>=$AJ$1,AN38<60,AA38>$AH$5),$AJ$5,0)),0) -> 0 | AD39: =IF(Z38>=$AJ$1,ROUNDDOWN(AD38*$AH$3%/($AH$2*2%),-1),0) -> 0 | AP39: =IF($H38*I39>150000,ROUNDDOWN(($H38*I39-150000)*6%*45%,0),0) -> 0 | AQ39: =IF($H38*J39>150000,ROUNDDOWN(($H38*J39-150000)*6%*45%,0),0) -> 0 | AR39: =IF($H38*K39>150000,ROUNDDOWN(($H38*K39-150000)*6%*45%,0),0) -> 0 | AS39: =IF($H38*L39>150000,ROUNDDOWN(($H38*L39-150000)*6%*45%,0),0) -> 0 | AT39: =IF($H38*M39>150000,ROUNDDOWN(($H38*M39-150000)*6%*45%,0),0) -> 0 | AU39: =IF($H38*N39>150000,ROUNDDOWN(($H38*N39-150000)*6%*45%,0),0) -> 0 | AV39: =IF($H38*O39>150000,ROUNDDOWN(($H38*O39-150000)*6%*45%,0),0) -> 0 | AW39: =IF($H38*P39>150000,ROUNDDOWN(($H38*P39-150000)*6%*45%,0),0) -> 0 | ... BE39: =IF($H38*X39>150000,ROUNDDOWN(($H38*X39-150000)*6%*45%,0),0) -> 0
A40: 19 | B40: =IF(LEN(D40)>1,IF(VALUE(MID(RIGHT(D40,7),1,1))>4,"외국인",IF(VALUE(RIGHT(11-MOD((MID(D40,1,1)*2+MID(D40,2,1)*3+MID(D40,3,1)*4+MID(D40,4,1)*5+MID(D40,5,1)*6+MID(D40,6,1)*7+MID(RIGHT(D40,7),1,1)*8+MID(RIGHT(D40,7),2,1)*9+MID(RIGHT(D40,7),3,1)*2+MID(RIGHT(D40,7),4,1)*3+MID(RIGHT(D40,7),5,1)*4+MID(RIGHT(D40,7),6,1)*5),11),1))=VALUE(RIGHT(D40,1)),"","오류")),"") | Y40: =SUM(I40:X41) -> 0 | Z40: =COUNTIF(I40:X41,">0") -> 0 | AA40: =H40*Y40 -> 0 | AB40: =IF(AO40<1000, 0, AO40) -> 0 | AC40: =IF(IFERROR($AN40<65,FALSE), IF(B40<>"외국인", ROUNDDOWN(AA40*$AH$1%,-1), IF(AND(AM40<>"", ISNUMBER(SEARCH(LEFT(SUBSTITUTE(AM40, "-",""),2), "F2_F5_F6"))), ROUNDDOWN(AA40*$AH$1%,-1), 0)),0) -> 0 | AD40: =IF(Z40>=$AJ$1,ROUNDDOWN(AA40*$AH$2%,-1),0) -> 0 | AE40: =AB40+AC40+AB41+AC41+AD40+AD41 -> 0 | AF40: =AA40-AE40 -> 0 | AN40: =IFERROR(DATEDIF(DATE(IF(ISNUMBER(FIND(MID( SUBSTITUTE(D40, "-",""), 7, 1), "3478")), 2000, 1900)+MID(D40,1,2), MID(D40,3,2), MID(D40,5,2)), TODAY(), "Y"),"") | AO40: =ROUNDDOWN(SUM(AP40:BE41),-1) -> 0 | AP40: =IF($H40*I40>150000,ROUNDDOWN(($H40*I40-150000)*6%*45%,0),0) -> 0 | AQ40: =IF($H40*J40>150000,ROUNDDOWN(($H40*J40-150000)*6%*45%,0),0) -> 0 | AR40: =IF($H40*K40>150000,ROUNDDOWN(($H40*K40-150000)*6%*45%,0),0) -> 0 | AS40: =IF($H40*L40>150000,ROUNDDOWN(($H40*L40-150000)*6%*45%,0),0) -> 0 | AT40: =IF($H40*M40>150000,ROUNDDOWN(($H40*M40-150000)*6%*45%,0),0) -> 0 | AU40: =IF($H40*N40>150000,ROUNDDOWN(($H40*N40-150000)*6%*45%,0),0) -> 0 | AV40: =IF($H40*O40>150000,ROUNDDOWN(($H40*O40-150000)*6%*45%,0),0) -> 0 | AW40: =IF($H40*P40>150000,ROUNDDOWN(($H40*P40-150000)*6%*45%,0),0) -> 0 | ... BD40: =IF($H40*W40>150000,ROUNDDOWN(($H40*W40-150000)*6%*45%,0),0) -> 0 | BG40: =C40 -> 0 | BM40: =BK40*BL40 -> 0 | BV40: =BM40+BP40-BU40 -> 0
...

Sheet 계좌(노임)
A1: ■ 지급금액 산출
A2: 현장명 : 현장별 노무비 정산 | C2: (양평군,김포시,강동구,종로구) | G2: 기타: | L2: 10월분
A3: 성 명 | C3: 지급계좌 | E3: =#REF! -> #REF! | F3: =#REF! -> #REF! | G3: =#REF! -> #REF! | H3: =#REF! -> #REF! | I3: =#REF! -> #REF! | J3: =#REF! -> #REF! | K3: 지급금액 | L3: 비 고
B4: 은행명 | C4: 계좌번호 | D4: 예금주 | E4: 1 | F4: 2 | G4: 3 | H4: 4 | I4: 5 | J4: 6
A5: =#REF! -> #REF! | B5: 국민은행 | C5: 467701-01-076012 | D5: =A5 -> #REF! | E5: =#REF! -> #REF! | F5: =#REF! -> #REF! | G5: =#REF! -> #REF! | H5: =#REF! -> #REF! | I5: =#REF! -> #REF! | J5: =#REF! -> #REF! | K5: =E5+F5+G5+H5+I5+J5 -> #REF! | L5: =K5+K6 -> #REF!
A6: =#REF! -> #REF! | B6: 국민은행 | C6: 467701-01-076013 | D6: =A6 -> #REF! | E6: =#REF! -> #REF! | F6: =#REF! -> #REF! | G6: =#REF! -> #REF! | H6: =#REF! -> #REF! | I6: =#REF! -> #REF! | J6: =#REF! -> #REF! | K6: =E6+F6+G6+H6+I6+J6 -> #REF!
A7: =#REF! -> #REF! | C7: 구팀장막내 | D7: =A7 -> #REF! | E7: =#REF! -> #REF! | F7: =#REF! -> #REF! | G7: =#REF! -> #REF! | H7: =#REF! -> #REF! | I7: =#REF! -> #REF! | J7: =#REF! -> #REF! | K7: =E7+F7+G7+H7+I7+J7 -> #REF! | L7: =K7+K8+K9+K10 -> #REF!
A8: =#REF! -> #REF! | B8: 국민은행 | C8: 824-24-0259-701 | D8: =A8 -> #REF! | E8: =#REF! -> #REF! | F8: =#REF! -> #REF! | G8: =#REF! -> #REF! | H8: =#REF! -> #REF! | I8: =#REF! -> #REF! | J8: =#REF! -> #REF! | K8: =E8+F8+G8+H8+I8+J8 -> #REF!
A9: =#REF! -> #REF! | B9: 국민은행 | C9: 824-24-0259-701 | D9: =A9 -> #REF! | E9: =#REF! -> #REF! | F9: =#REF! -> #REF! | G9: =#REF! -> #REF! | H9: =#REF! -> #REF! | I9: =#REF! -> #REF! | J9: =#REF! -> #REF! | K9: =E9+F9+G9+H9+I9+J9 -> #REF!
A10: =#REF! -> #REF! | B10: 농협은행 | C10: 356-1271-9970-53 | D10: =A10 -> #REF! | E10: =#REF! -> #REF! | F10: =#REF! -> #REF! | G10: =#REF! -> #REF! | H10: =#REF! -> #REF! | I10: =#REF! -> #REF! | J10: =#REF! -> #REF! | K10: =E10+F10+G10+H10+I10+J10 -> #REF!
A11: =#REF! -> #REF! | B11: 농협은행 | C11: 356-1271-9970-53 | D11: =A11 -> #REF! | E11: =#REF! -> #REF! | F11: =#REF! -> #REF! | G11: =#REF! -> #REF! | H11: =#REF! -> #REF! | I11: =#REF! -> #REF! | J11: =#REF! -> #REF! | K11: =E11+F11+G11+H11+I11+J11 -> #REF! | L11: =K11+K12 -> #REF!
A12: =#REF! -> #REF! | B12: 농협은행 | C12: 302-1293-9122-01 | D12: =A12 -> #REF! | E12: =#REF! -> #REF! | F12: =#REF! -> #REF! | G12: =#REF! -> #REF! | H12: =#REF! -> #REF! | I12: =#REF! -> #REF! | J12: =#REF! -> #REF! | K12: =E12+F12+G12+H12+I12+J12 -> #REF!
A13: =#REF! -> #REF! | B13: 농협은행 | C13: 302-1293-9122-02 | D13: =A13 -> #REF! | E13: =#REF! -> #REF! | F13: =#REF! -> #REF! | G13: =#REF! -> #REF! | H13: =#REF! -> #REF! | I13: =#REF! -> #REF! | J13: =#REF! -> #REF! | K13: =E13+F13+G13+H13+I13+J13 -> #REF! | L13: =K13+K14 -> #REF!
A14: =#REF! -> #REF! | B14: 우리은행 | C14: 1002-135-833724 | D14: =A14 -> #REF! | E14: =#REF! -> #REF! | F14: =#REF! -> #REF! | G14: =#REF! -> #REF! | H14: =#REF! -> #REF! | I14: =#REF! -> #REF! | J14: =#REF! -> #REF! | K14: =E14+F14+G14+H14+I14+J14 -> #REF!
A15: =#REF! -> #REF! | B15: 우리은행 | C15: 1002-135-833724 | D15: =A15 -> #REF! | E15: =#REF! -> #REF! | F15: =#REF! -> #REF! | G15: =#REF! -> #REF! | H15: =#REF! -> #REF! | I15: =#REF! -> #REF! | J15: =#REF! -> #REF! | K15: =E15+F15+G15+H15+I15+J15 -> #REF! | L15: =K15+K16 -> #REF!
A16: =#REF! -> #REF! | B16: 중소기업은행 | C16: 213-065905-02-018 | D16: =A16 -> #REF! | E16: =#REF! -> #REF! | F16: =#REF! -> #REF! | G16: =#REF! -> #REF! | H16: =#REF! -> #REF! | I16: =#REF! -> #REF! | J16: =#REF! -> #REF! | K16: =E16+F16+G16+H16+I16+J16 -> #REF!
A17: =#REF! -> #REF! | B17: 중소기업은행 | C17: 213-065905-02-018 | D17: =A17 -> #REF! | E17: =#REF! -> #REF! | F17: =#REF! -> #REF! | G17: =#REF! -> #REF! | H17: =#REF! -> #REF! | I17: =#REF! -> #REF! | J17: =#REF! -> #REF! | K17: =E17+F17+G17+H17+I17+J17 -> #REF!
A18: =#REF! -> #REF! | D18: =A18 -> #REF! | E18: =#REF! -> #REF! | F18: =#REF! -> #REF! | G18: =#REF! -> #REF! | H18: =#REF! -> #REF! | I18: =#REF! -> #REF! | J18: =#REF! -> #REF! | K18: =E18+F18+G18+H18+I18+J18 -> #REF!
A19: =#REF! -> #REF! | D19: =A19 -> #REF! | E19: =#REF! -> #REF! | F19: =#REF! -> #REF! | G19: =#REF! -> #REF! | H19: =#REF! -> #REF! | I19: =#REF! -> #REF! | J19: =#REF! -> #REF! | K19: =E19+F19+G19+H19+I19+J19 -> #REF! | L19: =K19+K20 -> #REF!
A20: =#REF! -> #REF! | B20: 우리은행 | C20: 1002-038-529333 | D20: =A20 -> #REF! | E20: =#REF! -> #REF! | F20: =#REF! -> #REF! | G20: =#REF! -> #REF! | H20: =#REF! -> #REF! | I20: =#REF! -> #REF! | J20: =#REF! -> #REF! | K20: =E20+F20+G20+H20+I20+J20 -> #REF!
A21: =#REF! -> #REF! | B21: 농협은행 | C21: 1290-01-011302 | D21: =A21 -> #REF! | E21: =#REF! -> #REF! | F21: =#REF! -> #REF! | G21: =#REF! -> #REF! | H21: =#REF! -> #REF! | I21: =#REF! -> #REF! | J21: =#REF! -> #REF! | K21: =E21+F21+G21+H21+I21+J21 -> #REF!
A22: =#REF! -> #REF! | D22: =A22 -> #REF! | E22: =#REF! -> #REF! | F22: =#REF! -> #REF! | G22: =#REF! -> #REF! | H22: =#REF! -> #REF! | I22: =#REF! -> #REF! | J22: =#REF! -> #REF! | K22: =E22+F22+G22+H22+I22+J22 -> #REF!
A23: =#REF! -> #REF! | B23: 우리은행 | C23: 1002-135-833724 | D23: =A23 -> #REF! | E23: =#REF! -> #REF! | F23: =#REF! -> #REF! | G23: =#REF! -> #REF! | H23: =#REF! -> #REF! | I23: =#REF! -> #REF! | J23: =#REF! -> #REF! | K23: =E23+F23+G23+H23+I23+J23 -> #REF!
A24: =#REF! -> #REF! | D24: =A24 -> #REF! | E24: =#REF! -> #REF! | F24: =#REF! -> #REF! | G24: =#REF! -> #REF! | H24: =#REF! -> #REF! | I24: =#REF! -> #REF! | J24: =#REF! -> #REF! | K24: =E24+F24+G24+H24+I24+J24 -> #REF!
A25: =#REF! -> #REF! | D25: =A25 -> #REF! | E25: =#REF! -> #REF! | F25: =#REF! -> #REF! | G25: =#REF! -> #REF! | H25: =#REF! -> #REF! | I25: =#REF! -> #REF! | J25: =#REF! -> #REF! | K25: =E25+F25+G25+H25+I25+J25 -> #REF!
A26: =#REF! -> #REF! | D26: =A26 -> #REF! | E26: =#REF! -> #REF! | F26: =#REF! -> #REF! | G26: =#REF! -> #REF! | H26: =#REF! -> #REF! | I26: =#REF! -> #REF! | J26: =#REF! -> #REF! | K26: =E26+F26+G26+H26+I26+J26 -> #REF!
A27: =#REF! -> #REF! | D27: =A27 -> #REF! | E27: =#REF! -> #REF! | F27: =#REF! -> #REF! | G27: =#REF! -> #REF! | H27: =#REF! -> #REF! | I27: =#REF! -> #REF! | J27: =#REF! -> #REF! | K27: =E27+F27+G27+H27+I27+J27 -> #REF!
A28: =#REF! -> #REF! | D28: =A28 -> #REF! | E28: =#REF! -> #REF! | F28: =#REF! -> #REF! | G28: =#REF! -> #REF! | H28: =#REF! -> #REF! | I28: =#REF! -> #REF! | J28: =#REF! -> #REF! | K28: =E28+F28+G28+H28+I28+J28 -> #REF!
A29: =#REF! -> #REF! | D29: =A29 -> #REF! | E29: =#REF! -> #REF! | F29: =#REF! -> #REF! | G29: =#REF! -> #REF! | H29: =#REF! -> #REF! | I29: =#REF! -> #REF! | J29: =#REF! -> #REF! | K29: =E29+F29+G29+H29+I29+J29 -> #REF!
A30: =#REF! -> #REF! | B30: 농협은행 | C30: 356-0873-8785-33 | D30: =A30 -> #REF! | E30: =#REF! -> #REF! | F30: =#REF! -> #REF! | G30: =#REF! -> #REF! | H30: =#REF! -> #REF! | I30: =#REF! -> #REF! | J30: =#REF! -> #REF! | K30: =E30+F30+G30+H30+I30+J30 -> #REF!
A31: =#REF! -> #REF! | B31: 신한은행 | C31: 110-257-461220 | D31: =A31 -> #REF! | E31: =#REF! -> #REF! | F31: =#REF! -> #REF! | G31: =#REF! -> #REF! | H31: =#REF! -> #REF! | I31: =#REF! -> #REF! | J31: =#REF! -> #REF! | K31: =E31+F31+G31+H31+I31+J31 -> #REF!
A32: =#REF! -> #REF! | B32: 우리은행 | C32: 1002-135-833724 | D32: =A32 -> #REF! | E32: =#REF! -> #REF! | F32: =#REF! -> #REF! | G32: =#REF! -> #REF! | H32: =#REF! -> #REF! | I32: =#REF! -> #REF! | J32: =#REF! -> #REF! | K32: =E32+F32+G32+H32+I32+J32 -> #REF!
A33: =#REF! -> #REF! | D33: =A33 -> #REF! | E33: =#REF! -> #REF! | F33: =#REF! -> #REF! | G33: =#REF! -> #REF! | H33: =#REF! -> #REF! | I33: =#REF! -> #REF! | J33: =#REF! -> #REF! | K33: =E33+F33+G33+H33+I33+J33 -> #REF!
A34: =#REF! -> #REF! | B34: 우리은행 | C34: 1002-038-529333 | D34: =A34 -> #REF! | E34: =#REF! -> #REF! | F34: =#REF! -> #REF! | G34: =#REF! -> #REF! | H34: =#REF! -> #REF! | I34: =#REF! -> #REF! | J34: =#REF! -> #REF! | K34: =E34+F34+G34+H34+I34+J34 -> #REF!
A35: =#REF! -> #REF! | B35: 제일은행 | C35: 626-20-447763 | D35: =A35 -> #REF! | E35: =#REF! -> #REF! | F35: =#REF! -> #REF! | G35: =#REF! -> #REF! | H35: =#REF! -> #REF! | I35: =#REF! -> #REF! | J35: =#REF! -> #REF! | K35: =E35+F35+G35+H35+I35+J35 -> #REF!
A36: =#REF! -> #REF! | B36: 농협은행 | C36: 356-02-040622 | D36: =A36 -> #REF! | E36: =#REF! -> #REF! | F36: =#REF! -> #REF! | G36: =#REF! -> #REF! | H36: =#REF! -> #REF! | I36: =#REF! -> #REF! | J36: =#REF! -> #REF! | K36: =E36+F36+G36+H36+I36+J36 -> #REF!
A37: =#REF! -> #REF! | B37: 김지은 반장 | C37: 010-6332-3822 | D37: =A37 -> #REF! | E37: =#REF! -> #REF! | F37: =#REF! -> #REF! | G37: =#REF! -> #REF! | H37: =#REF! -> #REF! | I37: =#REF! -> #REF! | J37: =#REF! -> #REF! | K37: =E37+F37+G37+H37+I37+J37 -> #REF!
A38: =#REF! -> #REF! | B38: 조반장 | D38: =A38 -> #REF! | E38: =#REF! -> #REF! | F38: =#REF! -> #REF! | G38: =#REF! -> #REF! | H38: =#REF! -> #REF! | I38: =#REF! -> #REF! | J38: =#REF! -> #REF! | K38: =E38+F38+G38+H38+I38+J38 -> #REF!
A39: =#REF! -> #REF! | D39: =A39 -> #REF! | E39: =#REF! -> #REF! | F39: =#REF! -> #REF! | G39: =#REF! -> #REF! | H39: =#REF! -> #REF! | I39: =#REF! -> #REF! | J39: =#REF! -> #REF! | K39: =E39+F39+G39+H39+I39+J39 -> #REF!
A40: =#REF! -> #REF! | D40: =A40 -> #REF! | E40: =#REF! -> #REF! | F40: =#REF! -> #REF! | G40: =#REF! -> #REF! | H40: =#REF! -> #REF! | I40: =#REF! -> #REF! | J40: =#REF! -> #REF! | K40: =E40+F40+G40+H40+I40+J40 -> #REF!
...

Sheet 계좌(장비)
A1: ■ 지급금액 산출
A2: 현장명 :현장별 장비대 정산 | B2: ='계좌(노임)'!$C$2 -> (양평군,김포시,강동구,종로구) | H2: ='계좌(노임)'!$G$2 -> 기타: | M2: ='계좌(노임)'!$L$2 -> 10월분
A3: 성 명 | B3: 규격 | C3: 은행명 | D3: 지급계좌 | G3: ='계좌(노임)'!F3 -> #REF! | H3: ='계좌(노임)'!G3 -> #REF! | I3: ='계좌(노임)'!H3 -> #REF! | J3: ='계좌(노임)'!I3 -> #REF! | K3: ='계좌(노임)'!J3 -> #REF! | L3: 지급금액 | M3: 비 고
D4: 계좌번호 | E4: 예금주 | F4: ='계좌(노임)'!E4 -> 1 | G4: ='계좌(노임)'!F4 -> 2 | H4: ='계좌(노임)'!G4 -> 3 | I4: ='계좌(노임)'!H4 -> 4 | J4: ='계좌(노임)'!I4 -> 5 | K4: ='계좌(노임)'!J4 -> 6
A5: =#REF! -> #REF! | B5: =#REF! -> #REF! | E5: =A5 -> #REF! | F5: =#REF! -> #REF! | G5: =#REF! -> #REF! | H5: =#REF! -> #REF! | I5: =#REF! -> #REF! | J5: =#REF! -> #REF! | K5: =#REF! -> #REF! | L5: =F5+G5+H5+I5+J5+K5 -> #REF! | M5: 부가세포함
A6: =#REF! -> #REF! | B6: =#REF! -> #REF! | E6: =A6 -> #REF! | F6: =#REF! -> #REF! | G6: =#REF! -> #REF! | H6: =#REF! -> #REF! | I6: =#REF! -> #REF! | J6: =#REF! -> #REF! | K6: =#REF! -> #REF! | L6: =F6+G6+H6+I6+J6+K6 -> #REF! | M6: 부가세포함
A7: =#REF! -> #REF! | B7: =#REF! -> #REF! | C7: 010-9143-0906 | D7: 서울크레인 | E7: =A7 -> #REF! | F7: =#REF! -> #REF! | G7: =#REF! -> #REF! | H7: =#REF! -> #REF! | I7: =#REF! -> #REF! | J7: =#REF! -> #REF! | K7: =#REF! -> #REF! | L7: =F7+G7+H7+I7+J7+K7 -> #REF! | M7: 부가세포함
A8: =#REF! -> #REF! | B8: =#REF! -> #REF! | C8: 010-5449-1420 | D8: 중앙크레인 | E8: =A8 -> #REF! | F8: =#REF! -> #REF! | G8: =#REF! -> #REF! | H8: =#REF! -> #REF! | I8: =#REF! -> #REF! | J8: =#REF! -> #REF! | K8: =#REF! -> #REF! | L8: =F8+G8+H8+I8+J8+K8 -> #REF! | M8: 부가세포함
A9: =#REF! -> #REF! | B9: =#REF! -> #REF! | D9: 영창크레인 | E9: =A9 -> #REF! | F9: =#REF! -> #REF! | G9: =#REF! -> #REF! | H9: =#REF! -> #REF! | I9: =#REF! -> #REF! | J9: =#REF! -> #REF! | K9: =#REF! -> #REF! | L9: =F9+G9+H9+I9+J9+K9 -> #REF! | M9: 부가세포함
